Workbook

Sheet List
A1: Fixed Lists | C1: Fill in white cells only
A2: Phases | B2: Position | C2: Region | D2: Assign To | E2: Editing Reason | G2: Lisence Type | H2: Project Types | J2: تبدأ مرحلة الدراسة بعد توقيع العقد بـ .... أيام | K2: تبدأ مرحلة التصميم بعد اعتماد مرحلة الدراسة بـ .... أيام | M2: Holidays | O2: Phase | P2: Reply Reason | Q2: Allowance Times | R2: Wieght (Reduction)
A3: Studies | B3: Head Dep | C3: Riyadh | D3: Client | E3: Devlopment | G3: Amanah | H3: Residential | M3: 45923 | O3: Studies | P3: Client Modification | Q3: 0
A4: Design | B4: Architect | C4: Cairo | D4: RCRC | E4: Internally | G4: TOD | H4: Commercial | J4: 10 | K4: 5 | M4: 46288 | O4: Studies | P4: Client Modification (Exceptional)
A5: Technical | B5: Quality Control | D5: R.M | E5: Client | G5: KSR | H5: Offices | M5: 46653 | O5: Studies | P5: Technical Mistake | Q5: 1 | R5: 0.15
B6: Interior Designer | D6: Design | E6: Govermental | G6: RCRC | H6: Mixed-Use | M6: 47019 | O6: Studies | P6: ...
B7: Draftsman | D7: Technical | E7: ... | G7: SBF | H7: High Rise | M7: 47384 | O7: Design | P7: Client Modification | Q7: 2
B8: Engineering department head assistant | D8: ... | G8: Corridors | H8: Culture | M8: 47749 | O8: Design | P8: Client Modification (Exceptional)
B9: Team Leader | G9: Wadi Hanifa | H9: Religious | M9: 45710 | O9: Design | P9: Technical Mistake | Q9: 1
B10: Structural Designer | G10: Commercial Nerve | H10: Resort | M10: 46075 | O10: Design | P10: G.C Modification (Problems)
B11: Electrical Engineer | G11: TOD + KSC | H11: Educational | M11: 46440 | O11: Design | P11: G.C Modification (Opinion)
B12: General Manager | G12: Madinah | H12: Interior | M12: 46805 | O12: Design | P12: ...
G13: Qassim Amanah | H13: Governmental | M13: 47171 | O13: Technical | P13: Client Modification | Q13: 2
G14: Other | H14: Others | M14: 47536 | O14: Technical | P14: Client Modification (Exceptional)
G15: N/A | H15: N/A | M15: 45746 | O15: Technical | P15: Technical Mistake | Q15: 2
M16: 45747 | O16: Technical | P16: Technical Mistake (Design Dep) | Q16: 0
M17: 45748 | O17: Technical | P17: G.C Modification (Problems)
M18: 46101 | O18: Technical | P18: G.C Modification (Opinion)
M19: 46102 | O19: Technical | P19: Reviewing the G.C
M20: 46103 | O20: Technical | P20: ...
M21: 46456
M22: 46457
M23: 46458
M24: 46810
M25: 46811
M26: 46812
M27: 47164
M28: 47165
M29: 47166
M30: 47519
M31: 47520
M32: 47521
... M56: 47590

Sheet Projects List
A1: =A4 -> Project | B1: =B4 -> Client | C1: =C4 -> Contract Code | D1: =D4 -> Signing Contract Date | E1: =E4 -> BUA | M2 | F1: =F4 -> Lisence Type | G1: =G4 -> Project Types | H1: =H4 -> Project Requirment | ... AI1: =AI4 -> TeamLeader3
A2: 1 | B2: 2 | C2: 3 | D2: 4 | E2: 5 | F2: 6 | G2: 7 | H2: 8 | I2: 9 | J2: 10 | K2: 11 | L2: 12 | M2: 13 | N2: 14 | O2: 15 | P2: 16 | Q2: 17 | R2: 18 | S2: 19 | T2: 20 | U2: 21 | V2: 22 | W2: 23 | X2: 24 | Y2: 25 | Z2: 26 | AA2: 27 | AB2: 28 | AC2: 29 | AD2: 30 | AE2: 31 | AF2: 32 | AG2: 33 | AH2: 34 | AI2: 35
A3: Projects List | B3: Projects List | D3: Fill in white cells only | K3: Study Phase | Q3: Design Phase | W3: Technical Phase
A4: Project | B4: Client | C4: Contract Code | D4: Signing Contract Date | E4: BUA | M2 | F4: Lisence Type | G4: Project Types | H4: Project Requirment | I4: Project Start Date | Contract | J4: Estimated End Date | K4: Stu. Team Leader | L4: Stu. Team Leader Working Percentage | M4: Stu. Start Date | Contract | N4: Stu. Duration | Contract | O4: Stu. Allowed Modification (Times) | P4: Stu. Modification days per time | Q4: Design Team Leader | R4: Design Team Leader Working Percentage | S4: Design. Start Date | Contract | T4: Design Duration | Contract | U4: Design Allowed Modification (Times) | V4: Design Modification days per time | W4: Tech. Team Leader | X4: Tech. Team Leader Working Percentage | Y4: Tech. Start Date | Contract | Z4: Tech. Duration | Contract | AA4: Tech. Allowed Modification (Times) | AB4: Tech. Modification days per time | AC4: Stu. Cost % | Contract Value | AD4: Design Cost % | Contract Value | AE4: Tech. Cost % | Contract Value | AF4: Contract Value | AG4: TeamLeader1 | AH4: TeamLeader2 | AI4: TeamLeader3
A5: Park View | B5: MOBTAKERON REAL ESTATE COMPANY | C5: REF.02.383 | D5: 45574 | E5: 7394 | F5: TOD | G5: Residential | H5: https://docs.google.com/spreadsheets/d/12b3TkOQbtVg1zjgbLLWYiSykhTxYcu7Vy4ZGWosqG5E/edit?usp=sharing | I5: =IF(الجدول1[[#This Row],[Signing Contract Date]]=0,0,WORKDAY.INTL(الجدول1[[#This Row],[Signing Contract Date]],List!$J$4,7,List!$M$3:$M$100)) -> 45588 | J5: =IF(Z5=0,0,WORKDAY.INTL(Y5,Z5+(AA5*AB5),7,List!$M$3:$M$100)) -> 45896 | L5: 0.25 | M5: =الجدول1[[#This Row],[Project Start Date | Contract]] -> 45588 | N5: 15 | O5: 0 | P5: 0 | Q5: Riyadh Almaghrabi | R5: 0.25 | S5: =IF(M5=0,0, WORKDAY.INTL( WORKDAY.INTL(M5,N5+(O5*P5),7,List!$M$3:$M$100),List!$K$4,7,List!$M$3:$M$100)) -> 45616 | T5: 70 | U5: 2 | V5: =10 -> 10 | X5: 0 | Y5: =IF(S5=0,0,WORKDAY.INTL(S5,T5+(U5*V5),7,List!$M$3:$M$100)) -> 45742 | Z5: 85 | AA5: =2 -> 2 | AB5: =10 -> 10 | AC5: 0.15 | AD5: 0.45 | AE5: 0.4 | AF5: 3500000 | AG5: =IF(الجدول1[[#This Row],[Stu. Team Leader]]=0,0,INDEX(Employees!$E:$E,MATCH(الجدول1[[#This Row],[Stu. Team Leader]],Employees!$C:$C,0))*الجدول1[[#This Row],[Stu. Team Leader Working Percentage]]) -> 0 | AH5: =IF(الجدول1[[#This Row],[Design Team Leader]]=0,0,INDEX(Employees!$E:$E,MATCH(الجدول1[[#This Row],[Design Team Leader]],Employees!$C:$C,0))*الجدول1[[#This Row],[Design Team Leader Working Percentage]]) -> 8603.9425 | AI5: =IF(الجدول1[[#This Row],[Tech. Team Leader]]=0,0,INDEX(Employees!$E:$E,MATCH(الجدول1[[#This Row],[Tech. Team Leader]],Employees!$C:$C,0))*الجدول1[[#This Row],[Tech. Team Leader Working Percentage]]) -> 0
A6: Details | B6: DETAILS REAL ESTATE COMPANY | C6: REF.02.387 | D6: 45635 | E6: 38881.2 | F6: Corridors | G6: Mixed-Use | I6: =IF(الجدول1[[#This Row],[Signing Contract Date]]=0,0,WORKDAY.INTL(الجدول1[[#This Row],[Signing Contract Date]],List!$J$4,7,List!$M$3:$M$100)) -> 45649 | J6: =IF(Z6=0,0,WORKDAY.INTL(Y6,Z6+(AA6*AB6),7,List!$M$3:$M$100)) -> 45922 | L6: 0.25 | M6: =الجدول1[[#This Row],[Project Start Date | Contract]] -> 45649 | N6: 15 | O6: 0 | P6: 0 | Q6: Riyadh Almaghrabi | R6: 0.3 | S6: =IF(M6=0,0, WORKDAY.INTL( WORKDAY.INTL(M6,N6+(O6*P6),7,List!$M$3:$M$100),List!$K$4,7,List!$M$3:$M$100)) -> 45677 | T6: 70 | U6: 2 | V6: 10 | X6: 0 | Y6: =IF(S6=0,0,WORKDAY.INTL(S6,T6+(U6*V6),7,List!$M$3:$M$100)) -> 45806 | Z6: 60 | AA6: 2 | AB6: 10 | AC6: 0.15 | AD6: 0.45 | AE6: 0.4 | AF6: 1500000 | AG6: =IF(الجدول1[[#This Row],[Stu. Team Leader]]=0,0,INDEX(Employees!$E:$E,MATCH(الجدول1[[#This Row],[Stu. Team Leader]],Employees!$C:$C,0))*الجدول1[[#This Row],[Stu. Team Leader Working Percentage]]) -> 0 | AH6: =IF(الجدول1[[#This Row],[Design Team Leader]]=0,0,INDEX(Employees!$E:$E,MATCH(الجدول1[[#This Row],[Design Team Leader]],Employees!$C:$C,0))*الجدول1[[#This Row],[Design Team Leader Working Percentage]]) -> 10324.731 | AI6: =IF(الجدول1[[#This Row],[Tech. Team Leader]]=0,0,INDEX(Employees!$E:$E,MATCH(الجدول1[[#This Row],[Tech. Team Leader]],Employees!$C:$C,0))*الجدول1[[#This Row],[Tech. Team Leader Working Percentage]]) -> 0
A7: Jevan Tower | B7: MR. BANDAR BIN MOHAMMED AL MUSIRYIE | C7: REF.02.366 | D7: 45517 | E7: 24743.6 | F7: TOD | G7: Residential | I7: =IF(الجدول1[[#This Row],[Signing Contract Date]]=0,0,WORKDAY.INTL(الجدول1[[#This Row],[Signing Contract Date]],List!$J$4,7,List!$M$3:$M$100)) -> 45531 | J7: =IF(Z7=0,0,WORKDAY.INTL(Y7,Z7+(AA7*AB7),7,List!$M$3:$M$100)) -> 45802 | L7: 0.25 | M7: =الجدول1[[#This Row],[Project Start Date | Contract]] -> 45531 | N7: 15 | O7: 0 | P7: 0 | Q7: Ghadeer AlAmoudi | S7: =IF(M7=0,0, WORKDAY.INTL( WORKDAY.INTL(M7,N7+(O7*P7),7,List!$M$3:$M$100),List!$K$4,7,List!$M$3:$M$100)) -> 45559 | T7: 70 | U7: 2 | V7: 10 | X7: 1 | Y7: =IF(S7=0,0,WORKDAY.INTL(S7,T7+(U7*V7),7,List!$M$3:$M$100)) -> 45685 | Z7: 60 | AA7: 2 | AB7: 10 | AC7: 0.15 | AD7: 0.45 | AE7: 0.4 | AF7: 1500000 | AG7: =IF(الجدول1[[#This Row],[Stu. Team Leader]]=0,0,INDEX(Employees!$E:$E,MATCH(الجدول1[[#This Row],[Stu. Team Leader]],Employees!$C:$C,0))*الجدول1[[#This Row],[Stu. Team Leader Working Percentage]]) -> 0 | AH7: =IF(الجدول1[[#This Row],[Design Team Leader]]=0,0,INDEX(Employees!$E:$E,MATCH(الجدول1[[#This Row],[Design Team Leader]],Employees!$C:$C,0))*الجدول1[[#This Row],[Design Team Leader Working Percentage]]) -> 0 | AI7: =IF(الجدول1[[#This Row],[Tech. Team Leader]]=0,0,INDEX(Employees!$E:$E,MATCH(الجدول1[[#This Row],[Tech. Team Leader]],Employees!$C:$C,0))*الجدول1[[#This Row],[Tech. Team Leader Working Percentage]]) -> 0
A8: Al Hamra Mixed Use TOD Project | B8: Rabwa Al Omran Contracting Company | C8: REF.02.406 | D8: 45806 | E8: 29292 | F8: TOD | G8: Mixed-Use | I8: =IF(الجدول1[[#This Row],[Signing Contract Date]]=0,0,WORKDAY.INTL(الجدول1[[#This Row],[Signing Contract Date]],List!$J$4,7,List!$M$3:$M$100)) -> 45824 | J8: =IF(Z8=0,0,WORKDAY.INTL(Y8,Z8+(AA8*AB8),7,List!$M$3:$M$100)) -> 46092 | L8: 0.25 | M8: =الجدول1[[#This Row],[Project Start Date | Contract]] -> 45824 | N8: 15 | O8: 0 | P8: 0 | Q8: Riyadh Almaghrabi | R8: 0.3 | S8: =IF(M8=0,0, WORKDAY.INTL( WORKDAY.INTL(M8,N8+(O8*P8),7,List!$M$3:$M$100),List!$K$4,7,List!$M$3:$M$100)) -> 45852 | T8: 70 | U8: 2 | V8: 10 | X8: 0 | Y8: =IF(S8=0,0,WORKDAY.INTL(S8,T8+(U8*V8),7,List!$M$3:$M$100)) -> 45979 | Z8: 60 | AA8: 2 | AB8: 10 | AC8: 0.15 | AD8: 0.45 | AE8: 0.4 | AF8: 1500000 | AG8: =IF(الجدول1[[#This Row],[Stu. Team Leader]]=0,0,INDEX(Employees!$E:$E,MATCH(الجدول1[[#This Row],[Stu. Team Leader]],Employees!$C:$C,0))*الجدول1[[#This Row],[Stu. Team Leader Working Percentage]]) -> 0 | AH8: =IF(الجدول1[[#This Row],[Design Team Leader]]=0,0,INDEX(Employees!$E:$E,MATCH(الجدول1[[#This Row],[Design Team Leader]],Employees!$C:$C,0))*الجدول1[[#This Row],[Design Team Leader Working Percentage]]) -> 10324.731 | AI8: =IF(الجدول1[[#This Row],[Tech. Team Leader]]=0,0,INDEX(Employees!$E:$E,MATCH(الجدول1[[#This Row],[Tech. Team Leader]],Employees!$C:$C,0))*الجدول1[[#This Row],[Tech. Team Leader Working Percentage]]) -> 0
I9: =IF(الجدول1[[#This Row],[Signing Contract Date]]=0,0,WORKDAY.INTL(الجدول1[[#This Row],[Signing Contract Date]],List!$J$4,7,List!$M$3:$M$100)) -> 0 | J9: =IF(Z9=0,0,WORKDAY.INTL(Y9,Z9+(AA9*AB9),7,List!$M$3:$M$100)) -> 0 | M9: =الجدول1[[#This Row],[Project Start Date | Contract]] -> 0 | S9: =IF(M9=0,0, WORKDAY.INTL( WORKDAY.INTL(M9,N9+(O9*P9),7,List!$M$3:$M$100),List!$K$4,7,List!$M$3:$M$100)) -> 0 | Y9: =IF(S9=0,0,WORKDAY.INTL(S9,T9+(U9*V9),7,List!$M$3:$M$100)) -> 0 | AG9: =IF(الجدول1[[#This Row],[Stu. Team Leader]]=0,0,INDEX(Employees!$E:$E,MATCH(الجدول1[[#This Row],[Stu. Team Leader]],Employees!$C:$C,0))*الجدول1[[#This Row],[Stu. Team Leader Working Percentage]]) -> 0 | AH9: =IF(الجدول1[[#This Row],[Design Team Leader]]=0,0,INDEX(Employees!$E:$E,MATCH(الجدول1[[#This Row],[Design Team Leader]],Employees!$C:$C,0))*الجدول1[[#This Row],[Design Team Leader Working Percentage]]) -> 0 | AI9: =IF(الجدول1[[#This Row],[Tech. Team Leader]]=0,0,INDEX(Employees!$E:$E,MATCH(الجدول1[[#This Row],[Tech. Team Leader]],Employees!$C:$C,0))*الجدول1[[#This Row],[Tech. Team Leader Working Percentage]]) -> 0
I10: =IF(الجدول1[[#This Row],[Signing Contract Date]]=0,0,WORKDAY.INTL(الجدول1[[#This Row],[Signing Contract Date]],List!$J$4,7,List!$M$3:$M$100)) -> 0 | J10: =IF(Z10=0,0,WORKDAY.INTL(Y10,Z10+(AA10*AB10),7,List!$M$3:$M$100)) -> 0 | M10: =الجدول1[[#This Row],[Project Start Date | Contract]] -> 0 | S10: =IF(M10=0,0, WORKDAY.INTL( WORKDAY.INTL(M10,N10+(O10*P10),7,List!$M$3:$M$100),List!$K$4,7,List!$M$3:$M$100)) -> 0 | Y10: =IF(S10=0,0,WORKDAY.INTL(S10,T10+(U10*V10),7,List!$M$3:$M$100)) -> 0 | AG10: =IF(الجدول1[[#This Row],[Stu. Team Leader]]=0,0,INDEX(Employees!$E:$E,MATCH(الجدول1[[#This Row],[Stu. Team Leader]],Employees!$C:$C,0))*الجدول1[[#This Row],[Stu. Team Leader Working Percentage]]) -> 0 | AH10: =IF(الجدول1[[#This Row],[Design Team Leader]]=0,0,INDEX(Employees!$E:$E,MATCH(الجدول1[[#This Row],[Design Team Leader]],Employees!$C:$C,0))*الجدول1[[#This Row],[Design Team Leader Working Percentage]]) -> 0 | AI10: =IF(الجدول1[[#This Row],[Tech. Team Leader]]=0,0,INDEX(Employees!$E:$E,MATCH(الجدول1[[#This Row],[Tech. Team Leader]],Employees!$C:$C,0))*الجدول1[[#This Row],[Tech. Team Leader Working Percentage]]) -> 0
I11: =IF(الجدول1[[#This Row],[Signing Contract Date]]=0,0,WORKDAY.INTL(الجدول1[[#This Row],[Signing Contract Date]],List!$J$4,7,List!$M$3:$M$100)) -> 0 | J11: =IF(Z11=0,0,WORKDAY.INTL(Y11,Z11+(AA11*AB11),7,List!$M$3:$M$100)) -> 0 | M11: =الجدول1[[#This Row],[Project Start Date | Contract]] -> 0 | S11: =IF(M11=0,0, WORKDAY.INTL( WORKDAY.INTL(M11,N11+(O11*P11),7,List!$M$3:$M$100),List!$K$4,7,List!$M$3:$M$100)) -> 0 | Y11: =IF(S11=0,0,WORKDAY.INTL(S11,T11+(U11*V11),7,List!$M$3:$M$100)) -> 0 | AG11: =IF(الجدول1[[#This Row],[Stu. Team Leader]]=0,0,INDEX(Employees!$E:$E,MATCH(الجدول1[[#This Row],[Stu. Team Leader]],Employees!$C:$C,0))*الجدول1[[#This Row],[Stu. Team Leader Working Percentage]]) -> 0 | AH11: =IF(الجدول1[[#This Row],[Design Team Leader]]=0,0,INDEX(Employees!$E:$E,MATCH(الجدول1[[#This Row],[Design Team Leader]],Employees!$C:$C,0))*الجدول1[[#This Row],[Design Team Leader Working Percentage]]) -> 0 | AI11: =IF(الجدول1[[#This Row],[Tech. Team Leader]]=0,0,INDEX(Employees!$E:$E,MATCH(الجدول1[[#This Row],[Tech. Team Leader]],Employees!$C:$C,0))*الجدول1[[#This Row],[Tech. Team Leader Working Percentage]]) -> 0
I12: =IF(الجدول1[[#This Row],[Signing Contract Date]]=0,0,WORKDAY.INTL(الجدول1[[#This Row],[Signing Contract Date]],List!$J$4,7,List!$M$3:$M$100)) -> 0 | J12: =IF(Z12=0,0,WORKDAY.INTL(Y12,Z12+(AA12*AB12),7,List!$M$3:$M$100)) -> 0 | M12: =الجدول1[[#This Row],[Project Start Date | Contract]] -> 0 | S12: =IF(M12=0,0, WORKDAY.INTL( WORKDAY.INTL(M12,N12+(O12*P12),7,List!$M$3:$M$100),List!$K$4,7,List!$M$3:$M$100)) -> 0 | Y12: =IF(S12=0,0,WORKDAY.INTL(S12,T12+(U12*V12),7,List!$M$3:$M$100)) -> 0 | AG12: =IF(الجدول1[[#This Row],[Stu. Team Leader]]=0,0,INDEX(Employees!$E:$E,MATCH(الجدول1[[#This Row],[Stu. Team Leader]],Employees!$C:$C,0))*الجدول1[[#This Row],[Stu. Team Leader Working Percentage]]) -> 0 | AH12: =IF(الجدول1[[#This Row],[Design Team Leader]]=0,0,INDEX(Employees!$E:$E,MATCH(الجدول1[[#This Row],[Design Team Leader]],Employees!$C:$C,0))*الجدول1[[#This Row],[Design Team Leader Working Percentage]]) -> 0 | AI12: =IF(الجدول1[[#This Row],[Tech. Team Leader]]=0,0,INDEX(Employees!$E:$E,MATCH(الجدول1[[#This Row],[Tech. Team Leader]],Employees!$C:$C,0))*الجدول1[[#This Row],[Tech. Team Leader Working Percentage]]) -> 0
I13: =IF(الجدول1[[#This Row],[Signing Contract Date]]=0,0,WORKDAY.INTL(الجدول1[[#This Row],[Signing Contract Date]],List!$J$4,7,List!$M$3:$M$100)) -> 0 | J13: =IF(Z13=0,0,WORKDAY.INTL(Y13,Z13+(AA13*AB13),7,List!$M$3:$M$100)) -> 0 | M13: =الجدول1[[#This Row],[Project Start Date | Contract]] -> 0 | S13: =IF(M13=0,0, WORKDAY.INTL( WORKDAY.INTL(M13,N13+(O13*P13),7,List!$M$3:$M$100),List!$K$4,7,List!$M$3:$M$100)) -> 0 | Y13: =IF(S13=0,0,WORKDAY.INTL(S13,T13+(U13*V13),7,List!$M$3:$M$100)) -> 0 | AG13: =IF(الجدول1[[#This Row],[Stu. Team Leader]]=0,0,INDEX(Employees!$E:$E,MATCH(الجدول1[[#This Row],[Stu. Team Leader]],Employees!$C:$C,0))*الجدول1[[#This Row],[Stu. Team Leader Working Percentage]]) -> 0 | AH13: =IF(الجدول1[[#This Row],[Design Team Leader]]=0,0,INDEX(Employees!$E:$E,MATCH(الجدول1[[#This Row],[Design Team Leader]],Employees!$C:$C,0))*الجدول1[[#This Row],[Design Team Leader Working Percentage]]) -> 0 | AI13: =IF(الجدول1[[#This Row],[Tech. Team Leader]]=0,0,INDEX(Employees!$E:$E,MATCH(الجدول1[[#This Row],[Tech. Team Leader]],Employees!$C:$C,0))*الجدول1[[#This Row],[Tech. Team Leader Working Percentage]]) -> 0
I14: =IF(الجدول1[[#This Row],[Signing Contract Date]]=0,0,WORKDAY.INTL(الجدول1[[#This Row],[Signing Contract Date]],List!$J$4,7,List!$M$3:$M$100)) -> 0 | J14: =IF(Z14=0,0,WORKDAY.INTL(Y14,Z14+(AA14*AB14),7,List!$M$3:$M$100)) -> 0 | M14: =الجدول1[[#This Row],[Project Start Date | Contract]] -> 0 | S14: =IF(M14=0,0, WORKDAY.INTL( WORKDAY.INTL(M14,N14+(O14*P14),7,List!$M$3:$M$100),List!$K$4,7,List!$M$3:$M$100)) -> 0 | Y14: =IF(S14=0,0,WORKDAY.INTL(S14,T14+(U14*V14),7,List!$M$3:$M$100)) -> 0 | AG14: =IF(الجدول1[[#This Row],[Stu. Team Leader]]=0,0,INDEX(Employees!$E:$E,MATCH(الجدول1[[#This Row],[Stu. Team Leader]],Employees!$C:$C,0))*الجدول1[[#This Row],[Stu. Team Leader Working Percentage]]) -> 0 | AH14: =IF(الجدول1[[#This Row],[Design Team Leader]]=0,0,INDEX(Employees!$E:$E,MATCH(الجدول1[[#This Row],[Design Team Leader]],Employees!$C:$C,0))*الجدول1[[#This Row],[Design Team Leader Working Percentage]]) -> 0 | AI14: =IF(الجدول1[[#This Row],[Tech. Team Leader]]=0,0,INDEX(Employees!$E:$E,MATCH(الجدول1[[#This Row],[Tech. Team Leader]],Employees!$C:$C,0))*الجدول1[[#This Row],[Tech. Team Leader Working Percentage]]) -> 0
I15: =IF(الجدول1[[#This Row],[Signing Contract Date]]=0,0,WORKDAY.INTL(الجدول1[[#This Row],[Signing Contract Date]],List!$J$4,7,List!$M$3:$M$100)) -> 0 | J15: =IF(Z15=0,0,WORKDAY.INTL(Y15,Z15+(AA15*AB15),7,List!$M$3:$M$100)) -> 0 | M15: =الجدول1[[#This Row],[Project Start Date | Contract]] -> 0 | S15: =IF(M15=0,0, WORKDAY.INTL( WORKDAY.INTL(M15,N15+(O15*P15),7,List!$M$3:$M$100),List!$K$4,7,List!$M$3:$M$100)) -> 0 | Y15: =IF(S15=0,0,WORKDAY.INTL(S15,T15+(U15*V15),7,List!$M$3:$M$100)) -> 0 | AG15: =IF(الجدول1[[#This Row],[Stu. Team Leader]]=0,0,INDEX(Employees!$E:$E,MATCH(الجدول1[[#This Row],[Stu. Team Leader]],Employees!$C:$C,0))*الجدول1[[#This Row],[Stu. Team Leader Working Percentage]]) -> 0 | AH15: =IF(الجدول1[[#This Row],[Design Team Leader]]=0,0,INDEX(Employees!$E:$E,MATCH(الجدول1[[#This Row],[Design Team Leader]],Employees!$C:$C,0))*الجدول1[[#This Row],[Design Team Leader Working Percentage]]) -> 0 | AI15: =IF(الجدول1[[#This Row],[Tech. Team Leader]]=0,0,INDEX(Employees!$E:$E,MATCH(الجدول1[[#This Row],[Tech. Team Leader]],Employees!$C:$C,0))*الجدول1[[#This Row],[Tech. Team Leader Working Percentage]]) -> 0
I16: =IF(الجدول1[[#This Row],[Signing Contract Date]]=0,0,WORKDAY.INTL(الجدول1[[#This Row],[Signing Contract Date]],List!$J$4,7,List!$M$3:$M$100)) -> 0 | J16: =IF(Z16=0,0,WORKDAY.INTL(Y16,Z16+(AA16*AB16),7,List!$M$3:$M$100)) -> 0 | M16: =الجدول1[[#This Row],[Project Start Date | Contract]] -> 0 | S16: =IF(M16=0,0, WORKDAY.INTL( WORKDAY.INTL(M16,N16+(O16*P16),7,List!$M$3:$M$100),List!$K$4,7,List!$M$3:$M$100)) -> 0 | Y16: =IF(S16=0,0,WORKDAY.INTL(S16,T16+(U16*V16),7,List!$M$3:$M$100)) -> 0 | AG16: =IF(الجدول1[[#This Row],[Stu. Team Leader]]=0,0,INDEX(Employees!$E:$E,MATCH(الجدول1[[#This Row],[Stu. Team Leader]],Employees!$C:$C,0))*الجدول1[[#This Row],[Stu. Team Leader Working Percentage]]) -> 0 | AH16: =IF(الجدول1[[#This Row],[Design Team Leader]]=0,0,INDEX(Employees!$E:$E,MATCH(الجدول1[[#This Row],[Design Team Leader]],Employees!$C:$C,0))*الجدول1[[#This Row],[Design Team Leader Working Percentage]]) -> 0 | AI16: =IF(الجدول1[[#This Row],[Tech. Team Leader]]=0,0,INDEX(Employees!$E:$E,MATCH(الجدول1[[#This Row],[Tech. Team Leader]],Employees!$C:$C,0))*الجدول1[[#This Row],[Tech. Team Leader Working Percentage]]) -> 0
I17: =IF(الجدول1[[#This Row],[Signing Contract Date]]=0,0,WORKDAY.INTL(الجدول1[[#This Row],[Signing Contract Date]],List!$J$4,7,List!$M$3:$M$100)) -> 0 | J17: =IF(Z17=0,0,WORKDAY.INTL(Y17,Z17+(AA17*AB17),7,List!$M$3:$M$100)) -> 0 | M17: =الجدول1[[#This Row],[Project Start Date | Contract]] -> 0 | S17: =IF(M17=0,0, WORKDAY.INTL( WORKDAY.INTL(M17,N17+(O17*P17),7,List!$M$3:$M$100),List!$K$4,7,List!$M$3:$M$100)) -> 0 | Y17: =IF(S17=0,0,WORKDAY.INTL(S17,T17+(U17*V17),7,List!$M$3:$M$100)) -> 0 | AG17: =IF(الجدول1[[#This Row],[Stu. Team Leader]]=0,0,INDEX(Employees!$E:$E,MATCH(الجدول1[[#This Row],[Stu. Team Leader]],Employees!$C:$C,0))*الجدول1[[#This Row],[Stu. Team Leader Working Percentage]]) -> 0 | AH17: =IF(الجدول1[[#This Row],[Design Team Leader]]=0,0,INDEX(Employees!$E:$E,MATCH(الجدول1[[#This Row],[Design Team Leader]],Employees!$C:$C,0))*الجدول1[[#This Row],[Design Team Leader Working Percentage]]) -> 0 | AI17: =IF(الجدول1[[#This Row],[Tech. Team Leader]]=0,0,INDEX(Employees!$E:$E,MATCH(الجدول1[[#This Row],[Tech. Team Leader]],Employees!$C:$C,0))*الجدول1[[#This Row],[Tech. Team Leader Working Percentage]]) -> 0
I18: =IF(الجدول1[[#This Row],[Signing Contract Date]]=0,0,WORKDAY.INTL(الجدول1[[#This Row],[Signing Contract Date]],List!$J$4,7,List!$M$3:$M$100)) -> 0 | J18: =IF(Z18=0,0,WORKDAY.INTL(Y18,Z18+(AA18*AB18),7,List!$M$3:$M$100)) -> 0 | M18: =الجدول1[[#This Row],[Project Start Date | Contract]] -> 0 | S18: =IF(M18=0,0, WORKDAY.INTL( WORKDAY.INTL(M18,N18+(O18*P18),7,List!$M$3:$M$100),List!$K$4,7,List!$M$3:$M$100)) -> 0 | Y18: =IF(S18=0,0,WORKDAY.INTL(S18,T18+(U18*V18),7,List!$M$3:$M$100)) -> 0 | AG18: =IF(الجدول1[[#This Row],[Stu. Team Leader]]=0,0,INDEX(Employees!$E:$E,MATCH(الجدول1[[#This Row],[Stu. Team Leader]],Employees!$C:$C,0))*الجدول1[[#This Row],[Stu. Team Leader Working Percentage]]) -> 0 | AH18: =IF(الجدول1[[#This Row],[Design Team Leader]]=0,0,INDEX(Employees!$E:$E,MATCH(الجدول1[[#This Row],[Design Team Leader]],Employees!$C:$C,0))*الجدول1[[#This Row],[Design Team Leader Working Percentage]]) -> 0 | AI18: =IF(الجدول1[[#This Row],[Tech. Team Leader]]=0,0,INDEX(Employees!$E:$E,MATCH(الجدول1[[#This Row],[Tech. Team Leader]],Employees!$C:$C,0))*الجدول1[[#This Row],[Tech. Team Leader Working Percentage]]) -> 0
I19: =IF(الجدول1[[#This Row],[Signing Contract Date]]=0,0,WORKDAY.INTL(الجدول1[[#This Row],[Signing Contract Date]],List!$J$4,7,List!$M$3:$M$100)) -> 0 | J19: =IF(Z19=0,0,WORKDAY.INTL(Y19,Z19+(AA19*AB19),7,List!$M$3:$M$100)) -> 0 | M19: =الجدول1[[#This Row],[Project Start Date | Contract]] -> 0 | S19: =IF(M19=0,0, WORKDAY.INTL( WORKDAY.INTL(M19,N19+(O19*P19),7,List!$M$3:$M$100),List!$K$4,7,List!$M$3:$M$100)) -> 0 | Y19: =IF(S19=0,0,WORKDAY.INTL(S19,T19+(U19*V19),7,List!$M$3:$M$100)) -> 0 | AG19: =IF(الجدول1[[#This Row],[Stu. Team Leader]]=0,0,INDEX(Employees!$E:$E,MATCH(الجدول1[[#This Row],[Stu. Team Leader]],Employees!$C:$C,0))*الجدول1[[#This Row],[Stu. Team Leader Working Percentage]]) -> 0 | AH19: =IF(الجدول1[[#This Row],[Design Team Leader]]=0,0,INDEX(Employees!$E:$E,MATCH(الجدول1[[#This Row],[Design Team Leader]],Employees!$C:$C,0))*الجدول1[[#This Row],[Design Team Leader Working Percentage]]) -> 0 | AI19: =IF(الجدول1[[#This Row],[Tech. Team Leader]]=0,0,INDEX(Employees!$E:$E,MATCH(الجدول1[[#This Row],[Tech. Team Leader]],Employees!$C:$C,0))*الجدول1[[#This Row],[Tech. Team Leader Working Percentage]]) -> 0
I20: =IF(الجدول1[[#This Row],[Signing Contract Date]]=0,0,WORKDAY.INTL(الجدول1[[#This Row],[Signing Contract Date]],List!$J$4,7,List!$M$3:$M$100)) -> 0 | J20: =IF(Z20=0,0,WORKDAY.INTL(Y20,Z20+(AA20*AB20),7,List!$M$3:$M$100)) -> 0 | M20: =الجدول1[[#This Row],[Project Start Date | Contract]] -> 0 | S20: =IF(M20=0,0, WORKDAY.INTL( WORKDAY.INTL(M20,N20+(O20*P20),7,List!$M$3:$M$100),List!$K$4,7,List!$M$3:$M$100)) -> 0 | Y20: =IF(S20=0,0,WORKDAY.INTL(S20,T20+(U20*V20),7,List!$M$3:$M$100)) -> 0 | AG20: =IF(الجدول1[[#This Row],[Stu. Team Leader]]=0,0,INDEX(Employees!$E:$E,MATCH(الجدول1[[#This Row],[Stu. Team Leader]],Employees!$C:$C,0))*الجدول1[[#This Row],[Stu. Team Leader Working Percentage]]) -> 0 | AH20: =IF(الجدول1[[#This Row],[Design Team Leader]]=0,0,INDEX(Employees!$E:$E,MATCH(الجدول1[[#This Row],[Design Team Leader]],Employees!$C:$C,0))*الجدول1[[#This Row],[Design Team Leader Working Percentage]]) -> 0 | AI20: =IF(الجدول1[[#This Row],[Tech. Team Leader]]=0,0,INDEX(Employees!$E:$E,MATCH(الجدول1[[#This Row],[Tech. Team Leader]],Employees!$C:$C,0))*الجدول1[[#This Row],[Tech. Team Leader Working Percentage]]) -> 0
... I76: =IF(الجدول1[[#This Row],[Signing Contract Date]]=0,0,WORKDAY.INTL(الجدول1[[#This Row],[Signing Contract Date]],List!$J$4,7,List!$M$3:$M$100)) -> 0 | J76: =IF(Z76=0,0,WORKDAY.INTL(Y76,Z76+(AA76*AB76),7,List!$M$3:$M$100)) -> 0 | M76: =الجدول1[[#This Row],[Project Start Date | Contract]] -> 0 | S76: =IF(M76=0,0, WORKDAY.INTL( WORKDAY.INTL(M76,N76+(O76*P76),7,List!$M$3:$M$100),List!$K$4,7,List!$M$3:$M$100)) -> 0 | Y76: =IF(S76=0,0,WORKDAY.INTL(S76,T76+(U76*V76),7,List!$M$3:$M$100)) -> 0 | AG76: =IF(الجدول1[[#This Row],[Stu. Team Leader]]=0,0,INDEX(Employees!$E:$E,MATCH(الجدول1[[#This Row],[Stu. Team Leader]],Employees!$C:$C,0))*الجدول1[[#This Row],[Stu. Team Leader Working Percentage]]) -> 0 | AH76: =IF(الجدول1[[#This Row],[Design Team Leader]]=0,0,INDEX(Employees!$E:$E,MATCH(الجدول1[[#This Row],[Design Team Leader]],Employees!$C:$C,0))*الجدول1[[#This Row],[Design Team Leader Working Percentage]]) -> 0 | AI76: =IF(الجدول1[[#This Row],[Tech. Team Leader]]=0,0,INDEX(Employees!$E:$E,MATCH(الجدول1[[#This Row],[Tech. Team Leader]],Employees!$C:$C,0))*الجدول1[[#This Row],[Tech. Team Leader Working Percentage]]) -> 0
I77: =IF(الجدول1[[#This Row],[Signing Contract Date]]=0,0,WORKDAY.INTL(الجدول1[[#This Row],[Signing Contract Date]],List!$J$4,7,List!$M$3:$M$100)) -> 0 | J77: =IF(Z77=0,0,WORKDAY.INTL(Y77,Z77+(AA77*AB77),7,List!$M$3:$M$100)) -> 0 | M77: =الجدول1[[#This Row],[Project Start Date | Contract]] -> 0 | S77: =IF(M77=0,0, WORKDAY.INTL( WORKDAY.INTL(M77,N77+(O77*P77),7,List!$M$3:$M$100),List!$K$4,7,List!$M$3:$M$100)) -> 0 | U77: =2 -> 2 | V77: =10 -> 10 | Y77: =IF(S77=0,0,WORKDAY.INTL(S77,T77+(U77*V77),7,List!$M$3:$M$100)) -> 0 | AG77: =IF(الجدول1[[#This Row],[Stu. Team Leader]]=0,0,INDEX(Employees!$E:$E,MATCH(الجدول1[[#This Row],[Stu. Team Leader]],Employees!$C:$C,0))*الجدول1[[#This Row],[Stu. Team Leader Working Percentage]]) -> 0 | AH77: =IF(الجدول1[[#This Row],[Design Team Leader]]=0,0,INDEX(Employees!$E:$E,MATCH(الجدول1[[#This Row],[Design Team Leader]],Employees!$C:$C,0))*الجدول1[[#This Row],[Design Team Leader Working Percentage]]) -> 0 | AI77: =IF(الجدول1[[#This Row],[Tech. Team Leader]]=0,0,INDEX(Employees!$E:$E,MATCH(الجدول1[[#This Row],[Tech. Team Leader]],Employees!$C:$C,0))*الجدول1[[#This Row],[Tech. Team Leader Working Percentage]]) -> 0
I78: =IF(الجدول1[[#This Row],[Signing Contract Date]]=0,0,WORKDAY.INTL(الجدول1[[#This Row],[Signing Contract Date]],List!$J$4,7,List!$M$3:$M$100)) -> 0 | J78: =IF(Z78=0,0,WORKDAY.INTL(Y78,Z78+(AA78*AB78),7,List!$M$3:$M$100)) -> 0 | M78: =الجدول1[[#This Row],[Project Start Date | Contract]] -> 0 | S78: =IF(M78=0,0, WORKDAY.INTL( WORKDAY.INTL(M78,N78+(O78*P78),7,List!$M$3:$M$100),List!$K$4,7,List!$M$3:$M$100)) -> 0 | U78: =2 -> 2 | V78: =10 -> 10 | Y78: =IF(S78=0,0,WORKDAY.INTL(S78,T78+(U78*V78),7,List!$M$3:$M$100)) -> 0 | AG78: =IF(الجدول1[[#This Row],[Stu. Team Leader]]=0,0,INDEX(Employees!$E:$E,MATCH(الجدول1[[#This Row],[Stu. Team Leader]],Employees!$C:$C,0))*الجدول1[[#This Row],[Stu. Team Leader Working Percentage]]) -> 0 | AH78: =IF(الجدول1[[#This Row],[Design Team Leader]]=0,0,INDEX(Employees!$E:$E,MATCH(الجدول1[[#This Row],[Design Team Leader]],Employees!$C:$C,0))*الجدول1[[#This Row],[Design Team Leader Working Percentage]]) -> 0 | AI78: =IF(الجدول1[[#This Row],[Tech. Team Leader]]=0,0,INDEX(Employees!$E:$E,MATCH(الجدول1[[#This Row],[Tech. Team Leader]],Employees!$C:$C,0))*الجدول1[[#This Row],[Tech. Team Leader Working Percentage]]) -> 0
I79: =IF(الجدول1[[#This Row],[Signing Contract Date]]=0,0,WORKDAY.INTL(الجدول1[[#This Row],[Signing Contract Date]],List!$J$4,7,List!$M$3:$M$100)) -> 0 | J79: =IF(Z79=0,0,WORKDAY.INTL(Y79,Z79+(AA79*AB79),7,List!$M$3:$M$100)) -> 0 | M79: =الجدول1[[#This Row],[Project Start Date | Contract]] -> 0 | S79: =IF(M79=0,0, WORKDAY.INTL( WORKDAY.INTL(M79,N79+(O79*P79),7,List!$M$3:$M$100),List!$K$4,7,List!$M$3:$M$100)) -> 0 | U79: =2 -> 2 | V79: =10 -> 10 | Y79: =IF(S79=0,0,WORKDAY.INTL(S79,T79+(U79*V79),7,List!$M$3:$M$100)) -> 0 | AG79: =IF(الجدول1[[#This Row],[Stu. Team Leader]]=0,0,INDEX(Employees!$E:$E,MATCH(الجدول1[[#This Row],[Stu. Team Leader]],Employees!$C:$C,0))*الجدول1[[#This Row],[Stu. Team Leader Working Percentage]]) -> 0 | AH79: =IF(الجدول1[[#This Row],[Design Team Leader]]=0,0,INDEX(Employees!$E:$E,MATCH(الجدول1[[#This Row],[Design Team Leader]],Employees!$C:$C,0))*الجدول1[[#This Row],[Design Team Leader Working Percentage]]) -> 0 | AI79: =IF(الجدول1[[#This Row],[Tech. Team Leader]]=0,0,INDEX(Employees!$E:$E,MATCH(الجدول1[[#This Row],[Tech. Team Leader]],Employees!$C:$C,0))*الجدول1[[#This Row],[Tech. Team Leader Working Percentage]]) -> 0
I80: =IF(الجدول1[[#This Row],[Signing Contract Date]]=0,0,WORKDAY.INTL(الجدول1[[#This Row],[Signing Contract Date]],List!$J$4,7,List!$M$3:$M$100)) -> 0 | J80: =IF(Z80=0,0,WORKDAY.INTL(Y80,Z80+(AA80*AB80),7,List!$M$3:$M$100)) -> 0 | M80: =الجدول1[[#This Row],[Project Start Date | Contract]] -> 0 | S80: =IF(M80=0,0, WORKDAY.INTL( WORKDAY.INTL(M80,N80+(O80*P80),7,List!$M$3:$M$100),List!$K$4,7,List!$M$3:$M$100)) -> 0 | U80: =2 -> 2 | V80: =10 -> 10 | Y80: =IF(S80=0,0,WORKDAY.INTL(S80,T80+(U80*V80),7,List!$M$3:$M$100)) -> 0 | AG80: =IF(الجدول1[[#This Row],[Stu. Team Leader]]=0,0,INDEX(Employees!$E:$E,MATCH(الجدول1[[#This Row],[Stu. Team Leader]],Employees!$C:$C,0))*الجدول1[[#This Row],[Stu. Team Leader Working Percentage]]) -> 0 | AH80: =IF(الجدول1[[#This Row],[Design Team Leader]]=0,0,INDEX(Employees!$E:$E,MATCH(الجدول1[[#This Row],[Design Team Leader]],Employees!$C:$C,0))*الجدول1[[#This Row],[Design Team Leader Working Percentage]]) -> 0 | AI80: =IF(الجدول1[[#This Row],[Tech. Team Leader]]=0,0,INDEX(Employees!$E:$E,MATCH(الجدول1[[#This Row],[Tech. Team Leader]],Employees!$C:$C,0))*الجدول1[[#This Row],[Tech. Team Leader Working Percentage]]) -> 0
I81: =IF(الجدول1[[#This Row],[Signing Contract Date]]=0,0,WORKDAY.INTL(الجدول1[[#This Row],[Signing Contract Date]],List!$J$4,7,List!$M$3:$M$100)) -> 0 | J81: =IF(Z81=0,0,WORKDAY.INTL(Y81,Z81+(AA81*AB81),7,List!$M$3:$M$100)) -> 0 | M81: =الجدول1[[#This Row],[Project Start Date | Contract]] -> 0 | S81: =IF(M81=0,0, WORKDAY.INTL( WORKDAY.INTL(M81,N81+(O81*P81),7,List!$M$3:$M$100),List!$K$4,7,List!$M$3:$M$100)) -> 0 | U81: =2 -> 2 | V81: =10 -> 10 | Y81: =IF(S81=0,0,WORKDAY.INTL(S81,T81+(U81*V81),7,List!$M$3:$M$100)) -> 0 | AA81: =2 -> 2 | AB81: =10 -> 10 | AG81: =IF(الجدول1[[#This Row],[Stu. Team Leader]]=0,0,INDEX(Employees!$E:$E,MATCH(الجدول1[[#This Row],[Stu. Team Leader]],Employees!$C:$C,0))*الجدول1[[#This Row],[Stu. Team Leader Working Percentage]]) -> 0 | AH81: =IF(الجدول1[[#This Row],[Design Team Leader]]=0,0,INDEX(Employees!$E:$E,MATCH(الجدول1[[#This Row],[Design Team Leader]],Employees!$C:$C,0))*الجدول1[[#This Row],[Design Team Leader Working Percentage]]) -> 0 | AI81: =IF(الجدول1[[#This Row],[Tech. Team Leader]]=0,0,INDEX(Employees!$E:$E,MATCH(الجدول1[[#This Row],[Tech. Team Leader]],Employees!$C:$C,0))*الجدول1[[#This Row],[Tech. Team Leader Working Percentage]]) -> 0
I82: =IF(الجدول1[[#This Row],[Signing Contract Date]]=0,0,WORKDAY.INTL(الجدول1[[#This Row],[Signing Contract Date]],List!$J$4,7,List!$M$3:$M$100)) -> 0 | J82: =IF(Z82=0,0,WORKDAY.INTL(Y82,Z82+(AA82*AB82),7,List!$M$3:$M$100)) -> 0 | M82: =الجدول1[[#This Row],[Project Start Date | Contract]] -> 0 | S82: =IF(M82=0,0, WORKDAY.INTL( WORKDAY.INTL(M82,N82+(O82*P82),7,List!$M$3:$M$100),List!$K$4,7,List!$M$3:$M$100)) -> 0 | U82: =2 -> 2 | V82: =10 -> 10 | Y82: =IF(S82=0,0,WORKDAY.INTL(S82,T82+(U82*V82),7,List!$M$3:$M$100)) -> 0 | AA82: =2 -> 2 | AB82: =10 -> 10 | AG82: =IF(الجدول1[[#This Row],[Stu. Team Leader]]=0,0,INDEX(Employees!$E:$E,MATCH(الجدول1[[#This Row],[Stu. Team Leader]],Employees!$C:$C,0))*الجدول1[[#This Row],[Stu. Team Leader Working Percentage]]) -> 0 | AH82: =IF(الجدول1[[#This Row],[Design Team Leader]]=0,0,INDEX(Employees!$E:$E,MATCH(الجدول1[[#This Row],[Design Team Leader]],Employees!$C:$C,0))*الجدول1[[#This Row],[Design Team Leader Working Percentage]]) -> 0 | AI82: =IF(الجدول1[[#This Row],[Tech. Team Leader]]=0,0,INDEX(Employees!$E:$E,MATCH(الجدول1[[#This Row],[Tech. Team Leader]],Employees!$C:$C,0))*الجدول1[[#This Row],[Tech. Team Leader Working Percentage]]) -> 0
I83: =IF(الجدول1[[#This Row],[Signing Contract Date]]=0,0,WORKDAY.INTL(الجدول1[[#This Row],[Signing Contract Date]],List!$J$4,7,List!$M$3:$M$100)) -> 0 | J83: =IF(Z83=0,0,WORKDAY.INTL(Y83,Z83+(AA83*AB83),7,List!$M$3:$M$100)) -> 0 | M83: =الجدول1[[#This Row],[Project Start Date | Contract]] -> 0 | S83: =IF(M83=0,0, WORKDAY.INTL( WORKDAY.INTL(M83,N83+(O83*P83),7,List!$M$3:$M$100),List!$K$4,7,List!$M$3:$M$100)) -> 0 | U83: =2 -> 2 | V83: =10 -> 10 | Y83: =IF(S83=0,0,WORKDAY.INTL(S83,T83+(U83*V83),7,List!$M$3:$M$100)) -> 0 | AA83: =2 -> 2 | AB83: =10 -> 10 | AG83: =IF(الجدول1[[#This Row],[Stu. Team Leader]]=0,0,INDEX(Employees!$E:$E,MATCH(الجدول1[[#This Row],[Stu. Team Leader]],Employees!$C:$C,0))*الجدول1[[#This Row],[Stu. Team Leader Working Percentage]]) -> 0 | AH83: =IF(الجدول1[[#This Row],[Design Team Leader]]=0,0,INDEX(Employees!$E:$E,MATCH(الجدول1[[#This Row],[Design Team Leader]],Employees!$C:$C,0))*الجدول1[[#This Row],[Design Team Leader Working Percentage]]) -> 0 | AI83: =IF(الجدول1[[#This Row],[Tech. Team Leader]]=0,0,INDEX(Employees!$E:$E,MATCH(الجدول1[[#This Row],[Tech. Team Leader]],Employees!$C:$C,0))*الجدول1[[#This Row],[Tech. Team Leader Working Percentage]]) -> 0
I84: =IF(الجدول1[[#This Row],[Signing Contract Date]]=0,0,WORKDAY.INTL(الجدول1[[#This Row],[Signing Contract Date]],List!$J$4,7,List!$M$3:$M$100)) -> 0 | J84: =IF(Z84=0,0,WORKDAY.INTL(Y84,Z84+(AA84*AB84),7,List!$M$3:$M$100)) -> 0 | M84: =الجدول1[[#This Row],[Project Start Date | Contract]] -> 0 | S84: =IF(M84=0,0, WORKDAY.INTL( WORKDAY.INTL(M84,N84+(O84*P84),7,List!$M$3:$M$100),List!$K$4,7,List!$M$3:$M$100)) -> 0 | U84: =2 -> 2 | V84: =10 -> 10 | Y84: =IF(S84=0,0,WORKDAY.INTL(S84,T84+(U84*V84),7,List!$M$3:$M$100)) -> 0 | AA84: =2 -> 2 | AB84: =10 -> 10 | AG84: =IF(الجدول1[[#This Row],[Stu. Team Leader]]=0,0,INDEX(Employees!$E:$E,MATCH(الجدول1[[#This Row],[Stu. Team Leader]],Employees!$C:$C,0))*الجدول1[[#This Row],[Stu. Team Leader Working Percentage]]) -> 0 | AH84: =IF(الجدول1[[#This Row],[Design Team Leader]]=0,0,INDEX(Employees!$E:$E,MATCH(الجدول1[[#This Row],[Design Team Leader]],Employees!$C:$C,0))*الجدول1[[#This Row],[Design Team Leader Working Percentage]]) -> 0 | AI84: =IF(الجدول1[[#This Row],[Tech. Team Leader]]=0,0,INDEX(Employees!$E:$E,MATCH(الجدول1[[#This Row],[Tech. Team Leader]],Employees!$C:$C,0))*الجدول1[[#This Row],[Tech. Team Leader Working Percentage]]) -> 0
I85: =IF(الجدول1[[#This Row],[Signing Contract Date]]=0,0,WORKDAY.INTL(الجدول1[[#This Row],[Signing Contract Date]],List!$J$4,7,List!$M$3:$M$100)) -> 0 | J85: =IF(Z85=0,0,WORKDAY.INTL(Y85,Z85+(AA85*AB85),7,List!$M$3:$M$100)) -> 0 | M85: =الجدول1[[#This Row],[Project Start Date | Contract]] -> 0 | S85: =IF(M85=0,0, WORKDAY.INTL( WORKDAY.INTL(M85,N85+(O85*P85),7,List!$M$3:$M$100),List!$K$4,7,List!$M$3:$M$100)) -> 0 | U85: =2 -> 2 | V85: =10 -> 10 | Y85: =IF(S85=0,0,WORKDAY.INTL(S85,T85+(U85*V85),7,List!$M$3:$M$100)) -> 0 | AA85: =2 -> 2 | AB85: =10 -> 10 | AG85: =IF(الجدول1[[#This Row],[Stu. Team Leader]]=0,0,INDEX(Employees!$E:$E,MATCH(الجدول1[[#This Row],[Stu. Team Leader]],Employees!$C:$C,0))*الجدول1[[#This Row],[Stu. Team Leader Working Percentage]]) -> 0 | AH85: =IF(الجدول1[[#This Row],[Design Team Leader]]=0,0,INDEX(Employees!$E:$E,MATCH(الجدول1[[#This Row],[Design Team Leader]],Employees!$C:$C,0))*الجدول1[[#This Row],[Design Team Leader Working Percentage]]) -> 0 | AI85: =IF(الجدول1[[#This Row],[Tech. Team Leader]]=0,0,INDEX(Employees!$E:$E,MATCH(الجدول1[[#This Row],[Tech. Team Leader]],Employees!$C:$C,0))*الجدول1[[#This Row],[Tech. Team Leader Working Percentage]]) -> 0
I86: =IF(الجدول1[[#This Row],[Signing Contract Date]]=0,0,WORKDAY.INTL(الجدول1[[#This Row],[Signing Contract Date]],List!$J$4,7,List!$M$3:$M$100)) -> 0 | J86: =IF(Z86=0,0,WORKDAY.INTL(Y86,Z86+(AA86*AB86),7,List!$M$3:$M$100)) -> 0 | M86: =الجدول1[[#This Row],[Project Start Date | Contract]] -> 0 | S86: =IF(M86=0,0, WORKDAY.INTL( WORKDAY.INTL(M86,N86+(O86*P86),7,List!$M$3:$M$100),List!$K$4,7,List!$M$3:$M$100)) -> 0 | U86: =2 -> 2 | V86: =10 -> 10 | Y86: =IF(S86=0,0,WORKDAY.INTL(S86,T86+(U86*V86),7,List!$M$3:$M$100)) -> 0 | AA86: =2 -> 2 | AB86: =10 -> 10 | AG86: =IF(الجدول1[[#This Row],[Stu. Team Leader]]=0,0,INDEX(Employees!$E:$E,MATCH(الجدول1[[#This Row],[Stu. Team Leader]],Employees!$C:$C,0))*الجدول1[[#This Row],[Stu. Team Leader Working Percentage]]) -> 0 | AH86: =IF(الجدول1[[#This Row],[Design Team Leader]]=0,0,INDEX(Employees!$E:$E,MATCH(الجدول1[[#This Row],[Design Team Leader]],Employees!$C:$C,0))*الجدول1[[#This Row],[Design Team Leader Working Percentage]]) -> 0 | AI86: =IF(الجدول1[[#This Row],[Tech. Team Leader]]=0,0,INDEX(Employees!$E:$E,MATCH(الجدول1[[#This Row],[Tech. Team Leader]],Employees!$C:$C,0))*الجدول1[[#This Row],[Tech. Team Leader Working Percentage]]) -> 0
I87: =IF(الجدول1[[#This Row],[Signing Contract Date]]=0,0,WORKDAY.INTL(الجدول1[[#This Row],[Signing Contract Date]],List!$J$4,7,List!$M$3:$M$100)) -> 0 | J87: =IF(Z87=0,0,WORKDAY.INTL(Y87,Z87+(AA87*AB87),7,List!$M$3:$M$100)) -> 0 | M87: =الجدول1[[#This Row],[Project Start Date | Contract]] -> 0 | S87: =IF(M87=0,0, WORKDAY.INTL( WORKDAY.INTL(M87,N87+(O87*P87),7,List!$M$3:$M$100),List!$K$4,7,List!$M$3:$M$100)) -> 0 | U87: =2 -> 2 | V87: =10 -> 10 | Y87: =IF(S87=0,0,WORKDAY.INTL(S87,T87+(U87*V87),7,List!$M$3:$M$100)) -> 0 | AA87: =2 -> 2 | AB87: =10 -> 10 | AG87: =IF(الجدول1[[#This Row],[Stu. Team Leader]]=0,0,INDEX(Employees!$E:$E,MATCH(الجدول1[[#This Row],[Stu. Team Leader]],Employees!$C:$C,0))*الجدول1[[#This Row],[Stu. Team Leader Working Percentage]]) -> 0 | AH87: =IF(الجدول1[[#This Row],[Design Team Leader]]=0,0,INDEX(Employees!$E:$E,MATCH(الجدول1[[#This Row],[Design Team Leader]],Employees!$C:$C,0))*الجدول1[[#This Row],[Design Team Leader Working Percentage]]) -> 0 | AI87: =IF(الجدول1[[#This Row],[Tech. Team Leader]]=0,0,INDEX(Employees!$E:$E,MATCH(الجدول1[[#This Row],[Tech. Team Leader]],Employees!$C:$C,0))*الجدول1[[#This Row],[Tech. Team Leader Working Percentage]]) -> 0
I88: =IF(الجدول1[[#This Row],[Signing Contract Date]]=0,0,WORKDAY.INTL(الجدول1[[#This Row],[Signing Contract Date]],List!$J$4,7,List!$M$3:$M$100)) -> 0 | J88: =IF(Z88=0,0,WORKDAY.INTL(Y88,Z88+(AA88*AB88),7,List!$M$3:$M$100)) -> 0 | M88: =الجدول1[[#This Row],[Project Start Date | Contract]] -> 0 | S88: =IF(M88=0,0, WORKDAY.INTL( WORKDAY.INTL(M88,N88+(O88*P88),7,List!$M$3:$M$100),List!$K$4,7,List!$M$3:$M$100)) -> 0 | U88: =2 -> 2 | V88: =10 -> 10 | Y88: =IF(S88=0,0,WORKDAY.INTL(S88,T88+(U88*V88),7,List!$M$3:$M$100)) -> 0 | AA88: =2 -> 2 | AB88: =10 -> 10 | AG88: =IF(الجدول1[[#This Row],[Stu. Team Leader]]=0,0,INDEX(Employees!$E:$E,MATCH(الجدول1[[#This Row],[Stu. Team Leader]],Employees!$C:$C,0))*الجدول1[[#This Row],[Stu. Team Leader Working Percentage]]) -> 0 | AH88: =IF(الجدول1[[#This Row],[Design Team Leader]]=0,0,INDEX(Employees!$E:$E,MATCH(الجدول1[[#This Row],[Design Team Leader]],Employees!$C:$C,0))*الجدول1[[#This Row],[Design Team Leader Working Percentage]]) -> 0 | AI88: =IF(الجدول1[[#This Row],[Tech. Team Leader]]=0,0,INDEX(Employees!$E:$E,MATCH(الجدول1[[#This Row],[Tech. Team Leader]],Employees!$C:$C,0))*الجدول1[[#This Row],[Tech. Team Leader Working Percentage]]) -> 0
I89: =IF(الجدول1[[#This Row],[Signing Contract Date]]=0,0,WORKDAY.INTL(الجدول1[[#This Row],[Signing Contract Date]],List!$J$4,7,List!$M$3:$M$100)) -> 0 | J89: =IF(Z89=0,0,WORKDAY.INTL(Y89,Z89+(AA89*AB89),7,List!$M$3:$M$100)) -> 0 | M89: =الجدول1[[#This Row],[Project Start Date | Contract]] -> 0 | S89: =IF(M89=0,0, WORKDAY.INTL( WORKDAY.INTL(M89,N89+(O89*P89),7,List!$M$3:$M$100),List!$K$4,7,List!$M$3:$M$100)) -> 0 | U89: =2 -> 2 | V89: =10 -> 10 | Y89: =IF(S89=0,0,WORKDAY.INTL(S89,T89+(U89*V89),7,List!$M$3:$M$100)) -> 0 | AA89: =2 -> 2 | AB89: =10 -> 10 | AG89: =IF(الجدول1[[#This Row],[Stu. Team Leader]]=0,0,INDEX(Employees!$E:$E,MATCH(الجدول1[[#This Row],[Stu. Team Leader]],Employees!$C:$C,0))*الجدول1[[#This Row],[Stu. Team Leader Working Percentage]]) -> 0 | AH89: =IF(الجدول1[[#This Row],[Design Team Leader]]=0,0,INDEX(Employees!$E:$E,MATCH(الجدول1[[#This Row],[Design Team Leader]],Employees!$C:$C,0))*الجدول1[[#This Row],[Design Team Leader Working Percentage]]) -> 0 | AI89: =IF(الجدول1[[#This Row],[Tech. Team Leader]]=0,0,INDEX(Employees!$E:$E,MATCH(الجدول1[[#This Row],[Tech. Team Leader]],Employees!$C:$C,0))*الجدول1[[#This Row],[Tech. Team Leader Working Percentage]]) -> 0
I90: =IF(الجدول1[[#This Row],[Signing Contract Date]]=0,0,WORKDAY.INTL(الجدول1[[#This Row],[Signing Contract Date]],List!$J$4,7,List!$M$3:$M$100)) -> 0 | J90: =IF(Z90=0,0,WORKDAY.INTL(Y90,Z90+(AA90*AB90),7,List!$M$3:$M$100)) -> 0 | M90: =الجدول1[[#This Row],[Project Start Date | Contract]] -> 0 | S90: =IF(M90=0,0, WORKDAY.INTL( WORKDAY.INTL(M90,N90+(O90*P90),7,List!$M$3:$M$100),List!$K$4,7,List!$M$3:$M$100)) -> 0 | U90: =2 -> 2 | V90: =10 -> 10 | Y90: =IF(S90=0,0,WORKDAY.INTL(S90,T90+(U90*V90),7,List!$M$3:$M$100)) -> 0 | AA90: =2 -> 2 | AB90: =10 -> 10 | AG90: =IF(الجدول1[[#This Row],[Stu. Team Leader]]=0,0,INDEX(Employees!$E:$E,MATCH(الجدول1[[#This Row],[Stu. Team Leader]],Employees!$C:$C,0))*الجدول1[[#This Row],[Stu. Team Leader Working Percentage]]) -> 0 | AH90: =IF(الجدول1[[#This Row],[Design Team Leader]]=0,0,INDEX(Employees!$E:$E,MATCH(الجدول1[[#This Row],[Design Team Leader]],Employees!$C:$C,0))*الجدول1[[#This Row],[Design Team Leader Working Percentage]]) -> 0 | AI90: =IF(الجدول1[[#This Row],[Tech. Team Leader]]=0,0,INDEX(Employees!$E:$E,MATCH(الجدول1[[#This Row],[Tech. Team Leader]],Employees!$C:$C,0))*الجدول1[[#This Row],[Tech. Team Leader Working Percentage]]) -> 0
I91: =IF(الجدول1[[#This Row],[Signing Contract Date]]=0,0,WORKDAY.INTL(الجدول1[[#This Row],[Signing Contract Date]],List!$J$4,7,List!$M$3:$M$100)) -> 0 | J91: =IF(Z91=0,0,WORKDAY.INTL(Y91,Z91+(AA91*AB91),7,List!$M$3:$M$100)) -> 0 | M91: =الجدول1[[#This Row],[Project Start Date | Contract]] -> 0 | S91: =IF(M91=0,0, WORKDAY.INTL( WORKDAY.INTL(M91,N91+(O91*P91),7,List!$M$3:$M$100),List!$K$4,7,List!$M$3:$M$100)) -> 0 | U91: =2 -> 2 | V91: =10 -> 10 | Y91: =IF(S91=0,0,WORKDAY.INTL(S91,T91+(U91*V91),7,List!$M$3:$M$100)) -> 0 | AA91: =2 -> 2 | AB91: =10 -> 10 | AG91: =IF(الجدول1[[#This Row],[Stu. Team Leader]]=0,0,INDEX(Employees!$E:$E,MATCH(الجدول1[[#This Row],[Stu. Team Leader]],Employees!$C:$C,0))*الجدول1[[#This Row],[Stu. Team Leader Working Percentage]]) -> 0 | AH91: =IF(الجدول1[[#This Row],[Design Team Leader]]=0,0,INDEX(Employees!$E:$E,MATCH(الجدول1[[#This Row],[Design Team Leader]],Employees!$C:$C,0))*الجدول1[[#This Row],[Design Team Leader Working Percentage]]) -> 0 | AI91: =IF(الجدول1[[#This Row],[Tech. Team Leader]]=0,0,INDEX(Employees!$E:$E,MATCH(الجدول1[[#This Row],[Tech. Team Leader]],Employees!$C:$C,0))*الجدول1[[#This Row],[Tech. Team Leader Working Percentage]]) -> 0
I92: =IF(الجدول1[[#This Row],[Signing Contract Date]]=0,0,WORKDAY.INTL(الجدول1[[#This Row],[Signing Contract Date]],List!$J$4,7,List!$M$3:$M$100)) -> 0 | J92: =IF(Z92=0,0,WORKDAY.INTL(Y92,Z92+(AA92*AB92),7,List!$M$3:$M$100)) -> 0 | M92: =الجدول1[[#This Row],[Project Start Date | Contract]] -> 0 | S92: =IF(M92=0,0, WORKDAY.INTL( WORKDAY.INTL(M92,N92+(O92*P92),7,List!$M$3:$M$100),List!$K$4,7,List!$M$3:$M$100)) -> 0 | U92: =2 -> 2 | V92: =10 -> 10 | Y92: =IF(S92=0,0,WORKDAY.INTL(S92,T92+(U92*V92),7,List!$M$3:$M$100)) -> 0 | AA92: =2 -> 2 | AB92: =10 -> 10 | AG92: =IF(الجدول1[[#This Row],[Stu. Team Leader]]=0,0,INDEX(Employees!$E:$E,MATCH(الجدول1[[#This Row],[Stu. Team Leader]],Employees!$C:$C,0))*الجدول1[[#This Row],[Stu. Team Leader Working Percentage]]) -> 0 | AH92: =IF(الجدول1[[#This Row],[Design Team Leader]]=0,0,INDEX(Employees!$E:$E,MATCH(الجدول1[[#This Row],[Design Team Leader]],Employees!$C:$C,0))*الجدول1[[#This Row],[Design Team Leader Working Percentage]]) -> 0 | AI92: =IF(الجدول1[[#This Row],[Tech. Team Leader]]=0,0,INDEX(Employees!$E:$E,MATCH(الجدول1[[#This Row],[Tech. Team Leader]],Employees!$C:$C,0))*الجدول1[[#This Row],[Tech. Team Leader Working Percentage]]) -> 0
... I205: =IF(الجدول1[[#This Row],[Signing Contract Date]]=0,0,WORKDAY.INTL(الجدول1[[#This Row],[Signing Contract Date]],List!$J$4,7,List!$M$3:$M$100)) -> 0 | J205: =IF(Z205=0,0,WORKDAY.INTL(Y205,Z205+(AA205*AB205),7,List!$M$3:$M$100)) -> 0 | M205: =الجدول1[[#This Row],[Project Start Date | Contract]] -> 0 | S205: =IF(M205=0,0, WORKDAY.INTL( WORKDAY.INTL(M205,N205+(O205*P205),7,List!$M$3:$M$100),List!$K$4,7,List!$M$3:$M$100)) -> 0 | U205: =2 -> 2 | V205: =10 -> 10 | Y205: =IF(S205=0,0,WORKDAY.INTL(S205,T205+(U205*V205),7,List!$M$3:$M$100)) -> 0 | AA205: =2 -> 2 | AB205: =10 -> 10 | AG205: =IF(الجدول1[[#This Row],[Stu. Team Leader]]=0,0,INDEX(Employees!$E:$E,MATCH(الجدول1[[#This Row],[Stu. Team Leader]],Employees!$C:$C,0))*الجدول1[[#This Row],[Stu. Team Leader Working Percentage]]) -> 0 | AH205: =IF(الجدول1[[#This Row],[Design Team Leader]]=0,0,INDEX(Employees!$E:$E,MATCH(الجدول1[[#This Row],[Design Team Leader]],Employees!$C:$C,0))*الجدول1[[#This Row],[Design Team Leader Working Percentage]]) -> 0 | AI205: =IF(الجدول1[[#This Row],[Tech. Team Leader]]=0,0,INDEX(Employees!$E:$E,MATCH(الجدول1[[#This Row],[Tech. Team Leader]],Employees!$C:$C,0))*الجدول1[[#This Row],[Tech. Team Leader Working Percentage]]) -> 0

Sheet KPI
C1: Fill in white cells only | F1: KPIs Data
B2: KPIs Item | C2: Wieght | F2: Project Allowance Delay (Days) | G2: Wieght for 1 Day Delay (Reduction) | K2: Level | L2: Max | M2: Min
B3: Employee Delay | C3: 0.5 | F3: 3 | G3: 0.01 | K3: A | L3: 1 | M3: =L4+0.01 -> 0.81
B4: Reply Reason | C4: 0.5 | K4: B | L4: 0.8 | M4: =L5+0.01 -> 0.61
C5: =SUM(C3:C4) -> 1 | K5: C | L5: 0.6 | M5: =L6+0.01 -> 0.41
K6: D | L6: 0.4 | M6: =L7+0.01 -> 0.21
K7: E | L7: 0.2 | M7: =L8+0.01 -> 0.01
K8: F | L8: 0

Sheet Tasks
C1: Tasks Durations (days) | D1: Fill in white cells only. Don't Leave Blank Rows. | F1: Check Phases Durations in Project List
A2: Code | B2: Phase | C2: Task Discribtion | D2: Task for: | F2: ='Projects List'!A5 -> Park View | G2: {=INDIRECT("'Projects List'!A"&5+COUNTA($F$2:F2))} -> Details | H2: {=INDIRECT("'Projects List'!A"&5+COUNTA($F$2:G2))} -> Jevan Tower | I2: {=INDIRECT("'Projects List'!A"&5+COUNTA($F$2:H2))} -> Al Hamra Mixed Use TOD Project | J2: {=INDIRECT("'Projects List'!A"&5+COUNTA($F$2:I2))} -> 0 | K2: {=INDIRECT("'Projects List'!A"&5+COUNTA($F$2:J2))} -> 0 | L2: {=INDIRECT("'Projects List'!A"&5+COUNTA($F$2:K2))} -> 0 | M2: {=INDIRECT("'Projects List'!A"&5+COUNTA($F$2:L2))} -> 0 | N2: {=INDIRECT("'Projects List'!A"&5+COUNTA($F$2:M2))} -> 0 | ... BM2: {=INDIRECT("'Projects List'!A"&5+COUNTA($F$2:BL2))} -> 0
A3: =B3&" "&C3 -> Studies Working on - Studies | B3: Studies | C3: Working on - Studies | D3: Internal | E3: =D3&COUNTIF(D$3:D3,D3) -> Internal1 | F3: 15 | G3: 15 | H3: 15 | I3: 15 | J3: 15 | K3: 15 | L3: 15 | M3: 15
A4: =B4&" "&C4 -> Studies ReWorking - Studies | B4: Studies | C4: ReWorking - Studies | D4: Internal | E4: =D4&COUNTIF(D$3:D4,D4) -> Internal2 | F4: 5 | G4: 5 | H4: 5 | I4: 5 | J4: 5 | K4: 5 | L4: 5 | M4: 5
A5: =B5&" "&C5 -> Studies ReWorking - Studies (VO) | B5: Studies | C5: ReWorking - Studies (VO) | D5: Internal | E5: =D5&COUNTIF(D$3:D5,D5) -> Internal3 | F5: 5 | G5: 5 | H5: 5 | I5: 5 | J5: 5 | K5: 5 | L5: 5 | M5: 5
A6: =B6&" "&C6 -> Studies Review and Comment - Studies | B6: Studies | C6: Review and Comment - Studies | D6: Client | E6: =D6&COUNTIF(D$3:D6,D6) -> Client1 | F6: 5 | G6: 5 | H6: 5 | I6: 5 | J6: 5 | K6: 5 | L6: 5 | M6: 5
A7: =B7&" "&C7 -> Studies Approved - Studies | B7: Studies | C7: Approved - Studies | D7: Client | E7: =D7&COUNTIF(D$3:D7,D7) -> Client2 | F7: 5 | G7: 5 | H7: 5 | I7: 5 | J7: 5 | K7: 5 | L7: 5 | M7: 5
B8: Design | C8: Working on - Design 25% | D8: Internal | E8: =D8&COUNTIF(D$3:D8,D8) -> Internal4 | F8: 20 | G8: 20 | H8: 20 | I8: 20 | J8: 20 | K8: 20 | L8: 20 | M8: 20
A9: =B9&" "&C9 -> Design ReWorking - Design 25% | B9: Design | C9: ReWorking - Design 25% | D9: Internal | E9: =D9&COUNTIF(D$3:D9,D9) -> Internal5 | F9: 10 | G9: 10 | H9: 10 | I9: 10 | J9: 10 | K9: 10 | L9: 10 | M9: 10
B10: Design | C10: ReWorking - Design 25% (VO) | D10: Internal | E10: =D10&COUNTIF(D$3:D10,D10) -> Internal6 | F10: 10 | G10: 10 | H10: 10 | I10: 10 | J10: 10 | K10: 10 | L10: 10 | M10: 10
B11: Design | C11: Review and Comment - Design 25% | D11: Client | E11: =D11&COUNTIF(D$3:D11,D11) -> Client3 | F11: 5 | G11: 5 | H11: 5 | I11: 5 | J11: 5 | K11: 5 | L11: 5 | M11: 5
B12: Design | C12: Approved - Design 25% | D12: Client | E12: =D12&COUNTIF(D$3:D12,D12) -> Client4 | F12: 1 | G12: 1 | H12: 1 | I12: 1 | J12: 1 | K12: 1 | L12: 1 | M12: 1
A13: =B13&" "&C13 -> Design Working on - Design 50% | B13: Design | C13: Working on - Design 50% | D13: Internal | E13: =D13&COUNTIF(D$3:D13,D13) -> Internal7 | F13: 20 | G13: 20 | H13: 20 | I13: 20 | J13: 20 | K13: 20 | L13: 20 | M13: 20
B14: Design | C14: ReWorking - Design 50% | D14: Internal | E14: =D14&COUNTIF(D$3:D14,D14) -> Internal8 | F14: 10 | G14: 10 | H14: 10 | I14: 10 | J14: 10 | K14: 10 | L14: 10 | M14: 10
A15: =B15&" "&C15 -> Design ReWorking - Design 50% (VO) | B15: Design | C15: ReWorking - Design 50% (VO) | D15: Internal | E15: =D15&COUNTIF(D$3:D15,D15) -> Internal9 | F15: 10 | G15: 10 | H15: 10 | I15: 10 | J15: 10 | K15: 10 | L15: 10 | M15: 10
A16: =B16&" "&C16 -> Design Review and Comment - Design 50% | B16: Design | C16: Review and Comment - Design 50% | D16: Client | E16: =D16&COUNTIF(D$3:D16,D16) -> Client5 | F16: 5 | G16: 5 | H16: 5 | I16: 5 | J16: 5 | K16: 5 | L16: 5 | M16: 5
A17: =B17&" "&C17 -> Design Approved - Design 50% | B17: Design | C17: Approved - Design 50% | D17: Client | E17: =D17&COUNTIF(D$3:D17,D17) -> Client6 | F17: 1 | G17: 1 | H17: 1 | I17: 1 | J17: 1 | K17: 1 | L17: 1 | M17: 1
B18: Design | C18: Working on - Design 75% | D18: Internal | E18: =D18&COUNTIF(D$3:D18,D18) -> Internal10 | F18: 20 | G18: 20 | H18: 20 | I18: 20 | J18: 20 | K18: 20 | L18: 20 | M18: 20
B19: Design | C19: ReWorking - Design 75% | D19: Internal | E19: =D19&COUNTIF(D$3:D19,D19) -> Internal11 | F19: 10 | G19: 10 | H19: 10 | I19: 10 | J19: 10 | K19: 10 | L19: 10 | M19: 10
B20: Design | C20: ReWorking - Design 75% (VO) | D20: Internal | E20: =D20&COUNTIF(D$3:D20,D20) -> Internal12 | F20: 10 | G20: 10 | H20: 10 | I20: 10 | J20: 10 | K20: 10 | L20: 10 | M20: 10
B21: Design | C21: Review and Comment - Design 75% | D21: Client | E21: =D21&COUNTIF(D$3:D21,D21) -> Client7 | F21: 5 | G21: 5 | H21: 5 | I21: 5 | J21: 5 | K21: 5 | L21: 5 | M21: 5
B22: Design | C22: Approved - Design 75% | D22: Client | E22: =D22&COUNTIF(D$3:D22,D22) -> Client8 | F22: 1 | G22: 1 | H22: 1 | I22: 1 | J22: 1 | K22: 1 | L22: 1 | M22: 1
B23: Design | C23: Working on - Design 100% | D23: Internal | E23: =D23&COUNTIF(D$3:D23,D23) -> Internal13 | F23: 20 | G23: 20 | H23: 20 | I23: 20 | J23: 20 | K23: 20 | L23: 20 | M23: 20
B24: Design | C24: ReWorking - Design 100% | D24: Internal | E24: =D24&COUNTIF(D$3:D24,D24) -> Internal14 | F24: 10 | G24: 10 | H24: 10 | I24: 10 | J24: 10 | K24: 10 | L24: 10 | M24: 10
B25: Design | C25: ReWorking - Design 100% (VO) | D25: Internal | E25: =D25&COUNTIF(D$3:D25,D25) -> Internal15 | F25: 10 | G25: 10 | H25: 10 | I25: 10 | J25: 10 | K25: 10 | L25: 10 | M25: 10
B26: Design | C26: Review and Comment - Design 100% | D26: Client | E26: =D26&COUNTIF(D$3:D26,D26) -> Client9 | F26: 5 | G26: 5 | H26: 5 | I26: 5 | J26: 5 | K26: 5 | L26: 5 | M26: 5
B27: Design | C27: Approved - Design 100% | D27: Client | E27: =D27&COUNTIF(D$3:D27,D27) -> Client10 | F27: 1 | G27: 1 | H27: 1 | I27: 1 | J27: 1 | K27: 1 | L27: 1 | M27: 1
B28: Design | C28: Issuing 1st to G.C | D28: Government | E28: =D28&COUNTIF(D$3:D28,D28) -> Government1 | F28: 1 | G28: 1 | H28: 1 | I28: 1 | J28: 1 | K28: 1 | L28: 1 | M28: 1
B29: Design | C29: Reissuing 1st to G.C | D29: Government | E29: =D29&COUNTIF(D$3:D29,D29) -> Government2 | F29: 10 | G29: 10 | H29: 10 | I29: 10 | J29: 10 | K29: 10 | L29: 10 | M29: 10
... B37: Technical | C37: Approval - Development | D37: Client | E37: =D37&COUNTIF(D$3:D37,D37) -> Client13 | F37: 1 | G37: 1 | H37: 1 | I37: 1 | J37: 1 | K37: 1 | L37: 1 | M37: 1
A38: =B38&" "&C38 -> Technical Working on - License | B38: Technical | C38: Working on - License | D38: Internal | E38: =D38&COUNTIF(D$3:D38,D38) -> Internal20 | F38: 10 | G38: 10 | H38: 10 | I38: 10 | J38: 10 | K38: 10 | L38: 10 | M38: 10
B39: Technical | C39: Issuing the license - R.M | D39: Government | E39: =D39&COUNTIF(D$3:D39,D39) -> Government4 | F39: 10 | G39: 10 | H39: 10 | I39: 10 | J39: 10 | K39: 10 | L39: 10 | M39: 10
B40: Technical | C40: Reworking & Issuing the license - R.M | D40: Internal | E40: =D40&COUNTIF(D$3:D40,D40) -> Internal21 | F40: 10 | G40: 10 | H40: 10 | I40: 10 | J40: 10 | K40: 10 | L40: 10 | M40: 10
B41: Technical | C41: Approval the License - R.M | D41: Government | E41: =D41&COUNTIF(D$3:D41,D41) -> Government5 | F41: 1 | G41: 1 | H41: 1 | I41: 1 | J41: 1 | K41: 1 | L41: 1 | M41: 1
B42: Technical | C42: Working on - D.D | D42: Internal | E42: =D42&COUNTIF(D$3:D42,D42) -> Internal22 | F42: 60 | G42: 60 | H42: 60 | I42: 60 | J42: 60 | K42: 60 | L42: 60 | M42: 60
A43: =B43&" "&C43 -> Technical ReWorking - D.D (VO) | B43: Technical | C43: ReWorking - D.D (VO) | D43: Internal | E43: =D43&COUNTIF(D$3:D43,D43) -> Internal23 | F43: 10 | G43: 10 | H43: 10 | I43: 10 | J43: 10 | K43: 10 | L43: 10 | M43: 10
B44: Technical | C44: Review and Comment - DD | D44: Client | E44: =D44&COUNTIF(D$3:D44,D44) -> Client14 | F44: 5 | G44: 5 | H44: 5 | I44: 5 | J44: 5 | K44: 5 | L44: 5 | M44: 5
B45: Technical | C45: Approval - DD | D45: Client | E45: =D45&COUNTIF(D$3:D45,D45) -> Client15 | F45: 1 | G45: 1 | H45: 1 | I45: 1 | J45: 1 | K45: 1 | L45: 1 | M45: 1
B46: Technical | C46: Working on 01 - BOQ | D46: Internal | E46: =D46&COUNTIF(D$3:D46,D46) -> Internal24 | F46: 10 | G46: 10 | H46: 10 | I46: 10 | J46: 10 | K46: 10 | L46: 10 | M46: 10
B47: Technical | C47: ReWorking - BOQ (VO) | D47: Internal | E47: =D47&COUNTIF(D$3:D47,D47) -> Internal25 | F47: 10 | G47: 10 | H47: 10 | I47: 10 | J47: 10 | K47: 10 | L47: 10 | M47: 10
...

Sheet External Tasks
A1: Code | B1: Phase | C1: Client Tasks | E1: Code | F1: Phase | G1: Government Tasks
A2: =B2&" "&C2 -> Studies Review and Comment - Studies | B2: =IF(C2="","",INDEX(Tasks!$B:$B,MATCH(C2,Tasks!$C:$C,0))) -> Studies | C2: =_xlfn.IFNA(INDEX(Tasks!C:C,MATCH("Client"&D2,Tasks!E:E,0)),"") -> Review and Comment - Studies | D2: 1 | E2: =F2&" "&G2 -> Design Issuing 1st to G.C | F2: =IF(G2="","",INDEX(Tasks!$B:$B,MATCH(G2,Tasks!$C:$C,0))) -> Design | G2: =_xlfn.IFNA(INDEX(Tasks!C:C,MATCH("Government"&D2,Tasks!E:E,0)),"") -> Issuing 1st to G.C
A3: =B3&" "&C3 -> Studies Approved - Studies | B3: =IF(C3="","",INDEX(Tasks!$B:$B,MATCH(C3,Tasks!$C:$C,0))) -> Studies | C3: =_xlfn.IFNA(INDEX(Tasks!C:C,MATCH("Client"&D3,Tasks!E:E,0)),"") -> Approved - Studies | D3: 2 | E3: =F3&" "&G3 -> Design Reissuing 1st to G.C | F3: =IF(G3="","",INDEX(Tasks!$B:$B,MATCH(G3,Tasks!$C:$C,0))) -> Design | G3: =_xlfn.IFNA(INDEX(Tasks!C:C,MATCH("Government"&D3,Tasks!E:E,0)),"") -> Reissuing 1st to G.C
A4: =B4&" "&C4 -> Design Review and Comment - Design 25% | B4: =IF(C4="","",INDEX(Tasks!$B:$B,MATCH(C4,Tasks!$C:$C,0))) -> Design | C4: =_xlfn.IFNA(INDEX(Tasks!C:C,MATCH("Client"&D4,Tasks!E:E,0)),"") -> Review and Comment - Design 25% | D4: 3 | E4: =F4&" "&G4 -> Design Approval 1st - License | F4: =IF(G4="","",INDEX(Tasks!$B:$B,MATCH(G4,Tasks!$C:$C,0))) -> Design | G4: =_xlfn.IFNA(INDEX(Tasks!C:C,MATCH("Government"&D4,Tasks!E:E,0)),"") -> Approval 1st - License
A5: =B5&" "&C5 -> Design Approved - Design 25% | B5: =IF(C5="","",INDEX(Tasks!$B:$B,MATCH(C5,Tasks!$C:$C,0))) -> Design | C5: =_xlfn.IFNA(INDEX(Tasks!C:C,MATCH("Client"&D5,Tasks!E:E,0)),"") -> Approved - Design 25% | D5: 4 | E5: =F5&" "&G5 -> Technical Issuing the license - R.M | F5: =IF(G5="","",INDEX(Tasks!$B:$B,MATCH(G5,Tasks!$C:$C,0))) -> Technical | G5: =_xlfn.IFNA(INDEX(Tasks!C:C,MATCH("Government"&D5,Tasks!E:E,0)),"") -> Issuing the license - R.M
A6: =B6&" "&C6 -> Design Review and Comment - Design 50% | B6: =IF(C6="","",INDEX(Tasks!$B:$B,MATCH(C6,Tasks!$C:$C,0))) -> Design | C6: =_xlfn.IFNA(INDEX(Tasks!C:C,MATCH("Client"&D6,Tasks!E:E,0)),"") -> Review and Comment - Design 50% | D6: 5 | E6: =F6&" "&G6 -> Technical Approval the License - R.M | F6: =IF(G6="","",INDEX(Tasks!$B:$B,MATCH(G6,Tasks!$C:$C,0))) -> Technical | G6: =_xlfn.IFNA(INDEX(Tasks!C:C,MATCH("Government"&D6,Tasks!E:E,0)),"") -> Approval the License - R.M
A7: =B7&" "&C7 -> Design Approved - Design 50% | B7: =IF(C7="","",INDEX(Tasks!$B:$B,MATCH(C7,Tasks!$C:$C,0))) -> Design | C7: =_xlfn.IFNA(INDEX(Tasks!C:C,MATCH("Client"&D7,Tasks!E:E,0)),"") -> Approved - Design 50% | D7: 6 | E7: =F7&" "&G7 | F7: =IF(G7="","",INDEX(Tasks!$B:$B,MATCH(G7,Tasks!$C:$C,0))) | G7: =_xlfn.IFNA(INDEX(Tasks!C:C,MATCH("Government"&D7,Tasks!E:E,0)),"")
A8: =B8&" "&C8 -> Design Review and Comment - Design 75% | B8: =IF(C8="","",INDEX(Tasks!$B:$B,MATCH(C8,Tasks!$C:$C,0))) -> Design | C8: =_xlfn.IFNA(INDEX(Tasks!C:C,MATCH("Client"&D8,Tasks!E:E,0)),"") -> Review and Comment - Design 75% | D8: 7 | E8: =F8&" "&G8 | F8: =IF(G8="","",INDEX(Tasks!$B:$B,MATCH(G8,Tasks!$C:$C,0))) | G8: =_xlfn.IFNA(INDEX(Tasks!C:C,MATCH("Government"&D8,Tasks!E:E,0)),"")
A9: =B9&" "&C9 -> Design Approved - Design 75% | B9: =IF(C9="","",INDEX(Tasks!$B:$B,MATCH(C9,Tasks!$C:$C,0))) -> Design | C9: =_xlfn.IFNA(INDEX(Tasks!C:C,MATCH("Client"&D9,Tasks!E:E,0)),"") -> Approved - Design 75% | D9: 8 | E9: =F9&" "&G9 | F9: =IF(G9="","",INDEX(Tasks!$B:$B,MATCH(G9,Tasks!$C:$C,0))) | G9: =_xlfn.IFNA(INDEX(Tasks!C:C,MATCH("Government"&D9,Tasks!E:E,0)),"")
A10: =B10&" "&C10 -> Design Review and Comment - Design 100% | B10: =IF(C10="","",INDEX(Tasks!$B:$B,MATCH(C10,Tasks!$C:$C,0))) -> Design | C10: =_xlfn.IFNA(INDEX(Tasks!C:C,MATCH("Client"&D10,Tasks!E:E,0)),"") -> Review and Comment - Design 100% | D10: 9 | E10: =F10&" "&G10 | F10: =IF(G10="","",INDEX(Tasks!$B:$B,MATCH(G10,Tasks!$C:$C,0))) | G10: =_xlfn.IFNA(INDEX(Tasks!C:C,MATCH("Government"&D10,Tasks!E:E,0)),"")
A11: =B11&" "&C11 -> Design Approved - Design 100% | B11: =IF(C11="","",INDEX(Tasks!$B:$B,MATCH(C11,Tasks!$C:$C,0))) -> Design | C11: =_xlfn.IFNA(INDEX(Tasks!C:C,MATCH("Client"&D11,Tasks!E:E,0)),"") -> Approved - Design 100% | D11: 10 | E11: =F11&" "&G11 | F11: =IF(G11="","",INDEX(Tasks!$B:$B,MATCH(G11,Tasks!$C:$C,0))) | G11: =_xlfn.IFNA(INDEX(Tasks!C:C,MATCH("Government"&D11,Tasks!E:E,0)),"")
A12: =B12&" "&C12 -> Design Coordinate with Out-source | B12: =IF(C12="","",INDEX(Tasks!$B:$B,MATCH(C12,Tasks!$C:$C,0))) -> Design | C12: =_xlfn.IFNA(INDEX(Tasks!C:C,MATCH("Client"&D12,Tasks!E:E,0)),"") -> Coordinate with Out-source | D12: 11 | E12: =F12&" "&G12 | F12: =IF(G12="","",INDEX(Tasks!$B:$B,MATCH(G12,Tasks!$C:$C,0))) | G12: =_xlfn.IFNA(INDEX(Tasks!C:C,MATCH("Government"&D12,Tasks!E:E,0)),"")
A13: =B13&" "&C13 -> Technical Review and Comment - Development | B13: =IF(C13="","",INDEX(Tasks!$B:$B,MATCH(C13,Tasks!$C:$C,0))) -> Technical | C13: =_xlfn.IFNA(INDEX(Tasks!C:C,MATCH("Client"&D13,Tasks!E:E,0)),"") -> Review and Comment - Development | D13: 12 | E13: =F13&" "&G13 | F13: =IF(G13="","",INDEX(Tasks!$B:$B,MATCH(G13,Tasks!$C:$C,0))) | G13: =_xlfn.IFNA(INDEX(Tasks!C:C,MATCH("Government"&D13,Tasks!E:E,0)),"")
... A100: =B100&" "&C100 | B100: =IF(C100="","",INDEX(Tasks!$B:$B,MATCH(C100,Tasks!$C:$C,0))) | C100: =_xlfn.IFNA(INDEX(Tasks!C:C,MATCH("Client"&D100,Tasks!E:E,0)),"") | D100: 99 | E100: =F100&" "&G100 | F100: =IF(G100="","",INDEX(Tasks!$B:$B,MATCH(G100,Tasks!$C:$C,0))) | G100: =_xlfn.IFNA(INDEX(Tasks!C:C,MATCH("Government"&D100,Tasks!E:E,0)),"")

Sheet Employees
D1: Employees Data | F1: Fill in white cells only
B3: Phase | C3: Employee | D3: Position | E3: Emoployee's Cost | Monthly | F3: Email | G3: Region
A4: =B4&" "&D4 -> Design | B4: Design | C4: Ahmed AL-Attas | E4: 27792.61 | G4: Riyadh | H4: =B4&" "&C4 -> Design Ahmed AL-Attas | J4: Abderrahmane Boukaiss | K4: a.boukaiss@cleardes.com
A5: =B5&" "&D5 -> Design Head Dep | B5: Design | C5: Younes Al-Ammar | D5: Head Dep | E5: 41317.05 | G5: Riyadh | H5: =B5&" "&C5 -> Design Younes Al-Ammar | J5: Salman Fahad Mulhim | K5: s.almulhim@cleardes.com
