Workbook
Name PrjctStartDate: 'Project Follow up - Report'!$H$8:$H$8
Name PrjctStartDate: 'Project Follow up - Base'!$H$12:$H$12
Name Project_Start: 'Project Follow up - Base'!#REF!
Name Project_Start: 'Project Follow up - Report'!#REF!
Name Scrolling_Increment: 'Project Follow up - Base'!#REF!
Name Scrolling_Increment: 'Project Follow up - Report'!#REF!

Sheet Home
D4: Database | H4: This Project | L4: All Projects
D6: Fixed Lists | H6: Data Entry File | L6: Employees' KPIs
D7: Project List | H7: Follow up - Base | L7: Departments' KPIs
D8: Tasks | H8: Follow up - Client Report
D9: Employees Data | H9: Project Costs
D10: KPIs Data | H10: Employees Summary
H11: Team Members Through Time
H12: Phases Through Time
H13: Employees KPIs

Sheet Team members Data
C3: ='Team Members Over Time'!F5 -> 45627 | D3: ='Team Members Over Time'!G5 -> 0 | E3: ='Team Members Over Time'!H5 -> 45658 | F3: ='Team Members Over Time'!I5 -> 0 | G3: ='Team Members Over Time'!J5 -> 45689 | H3: ='Team Members Over Time'!K5 -> 0 | I3: ='Team Members Over Time'!L5 -> 45717 | J3: ='Team Members Over Time'!M5 -> 0 | ... AL3: ='Team Members Over Time'!AO5 -> 0
A4: ='Project Follow up - Base'!$B$17 -> Studies | B4: ='Project Follow up - Base'!F20 -> Abdulrahman Bukees | C4: =IF('Project Follow up - Base'!$N20="",0, COUNTIFS('Project Follow up - Base'!$AC20:$OC20,"<="&10,'Project Follow up - Base'!$AC20:$OC20,">="&-10,'Project Follow up - Base'!$AC$3:$OC$3,">="&DATE(YEAR(C$3),MONTH(C$3),1),'Project Follow up - Base'!$AC$3:$OC$3,"<="&(DATE(YEAR(C$3),MONTH(C$3)+1,1)-1),'Project Follow up - Base'!$AC$4:$OC$4,"<>"&"Fri",'Project Follow up - Base'!$AC$4:$OC$4,"<>"&"Sat",'Project Follow up - Base'!$AC$3:$OC$3,"<>"&List!$L$3,'Project Follow up - Base'!$AC$3:$OC$3,"<>"&List!$L$4,'Project Follow up - Base'!$AC$3:$OC$3,"<>"&List!$L$5,'Project Follow up - Base'!$AC$3:$OC$3,"<>"&List!$L$6,'Project Follow up - Base'!$AC$3:$OC$3,"<>"&List!$L$7,'Project Follow up - Base'!$AC$3:$OC$3,"<>"&List!$L$8,'Project Follow up - Base'!$AC$3:$OC$3,"<>"&List!$L$9,'Project Follow up - Base'!$AC$3:$OC$3,"<>"&List!$L$10,'Project Follow up - Base'!$AC$3:$OC$3,"<>"&List!$L$11,'Project Follow up - Base'!$AC$3:$OC$3,"<>"&List!$L$12,'Project Follow up - Base'!$AC$3:$OC$3,"<>"&List!$L$13)) -> 6 | D4: =IF('Project Follow up - Base'!$N20="",0, COUNTIFS('Project Follow up - Base'!$AC20:$OC20,"<="&10,'Project Follow up - Base'!$AC20:$OC20,">="&-10,'Project Follow up - Base'!$AC$3:$OC$3,">="&DATE(YEAR(D$3),MONTH(D$3),1),'Project Follow up - Base'!$AC$3:$OC$3,"<="&(DATE(YEAR(D$3),MONTH(D$3)+1,1)-1),'Project Follow up - Base'!$AC$4:$OC$4,"<>"&"Fri",'Project Follow up - Base'!$AC$4:$OC$4,"<>"&"Sat",'Project Follow up - Base'!$AC$3:$OC$3,"<>"&List!$L$3,'Project Follow up - Base'!$AC$3:$OC$3,"<>"&List!$L$4,'Project Follow up - Base'!$AC$3:$OC$3,"<>"&List!$L$5,'Project Follow up - Base'!$AC$3:$OC$3,"<>"&List!$L$6,'Project Follow up - Base'!$AC$3:$OC$3,"<>"&List!$L$7,'Project Follow up - Base'!$AC$3:$OC$3,"<>"&List!$L$8,'Project Follow up - Base'!$AC$3:$OC$3,"<>"&List!$L$9,'Project Follow up - Base'!$AC$3:$OC$3,"<>"&List!$L$10,'Project Follow up - Base'!$AC$3:$OC$3,"<>"&List!$L$11,'Project Follow up - Base'!$AC$3:$OC$3,"<>"&List!$L$12,'Project Follow up - Base'!$AC$3:$OC$3,"<>"&List!$L$13)) -> 0 | E4: =IF('Project Follow up - Base'!$N20="",0, COUNTIFS('Project Follow up - Base'!$AC20:$OC20,"<="&10,'Project Follow up - Base'!$AC20:$OC20,">="&-10,'Project Follow up - Base'!$AC$3:$OC$3,">="&DATE(YEAR(E$3),MONTH(E$3),1),'Project Follow up - Base'!$AC$3:$OC$3,"<="&(DATE(YEAR(E$3),MONTH(E$3)+1,1)-1),'Project Follow up - Base'!$AC$4:$OC$4,"<>"&"Fri",'Project Follow up - Base'!$AC$4:$OC$4,"<>"&"Sat",'Project Follow up - Base'!$AC$3:$OC$3,"<>"&List!$L$3,'Project Follow up - Base'!$AC$3:$OC$3,"<>"&List!$L$4,'Project Follow up - Base'!$AC$3:$OC$3,"<>"&List!$L$5,'Project Follow up - Base'!$AC$3:$OC$3,"<>"&List!$L$6,'Project Follow up - Base'!$AC$3:$OC$3,"<>"&List!$L$7,'Project Follow up - Base'!$AC$3:$OC$3,"<>"&List!$L$8,'Project Follow up - Base'!$AC$3:$OC$3,"<>"&List!$L$9,'Project Follow up - Base'!$AC$3:$OC$3,"<>"&List!$L$10,'Project Follow up - Base'!$AC$3:$OC$3,"<>"&List!$L$11,'Project Follow up - Base'!$AC$3:$OC$3,"<>"&List!$L$12,'Project Follow up - Base'!$AC$3:$OC$3,"<>"&List!$L$13)) -> 8 | F4: =IF('Project Follow up - Base'!$N20="",0, COUNTIFS('Project Follow up - Base'!$AC20:$OC20,"<="&10,'Project Follow up - Base'!$AC20:$OC20,">="&-10,'Project Follow up - Base'!$AC$3:$OC$3,">="&DATE(YEAR(F$3),MONTH(F$3),1),'Project Follow up - Base'!$AC$3:$OC$3,"<="&(DATE(YEAR(F$3),MONTH(F$3)+1,1)-1),'Project Follow up - Base'!$AC$4:$OC$4,"<>"&"Fri",'Project Follow up - Base'!$AC$4:$OC$4,"<>"&"Sat",'Project Follow up - Base'!$AC$3:$OC$3,"<>"&List!$L$3,'Project Follow up - Base'!$AC$3:$OC$3,"<>"&List!$L$4,'Project Follow up - Base'!$AC$3:$OC$3,"<>"&List!$L$5,'Project Follow up - Base'!$AC$3:$OC$3,"<>"&List!$L$6,'Project Follow up - Base'!$AC$3:$OC$3,"<>"&List!$L$7,'Project Follow up - Base'!$AC$3:$OC$3,"<>"&List!$L$8,'Project Follow up - Base'!$AC$3:$OC$3,"<>"&List!$L$9,'Project Follow up - Base'!$AC$3:$OC$3,"<>"&List!$L$10,'Project Follow up - Base'!$AC$3:$OC$3,"<>"&List!$L$11,'Project Follow up - Base'!$AC$3:$OC$3,"<>"&List!$L$12,'Project Follow up - Base'!$AC$3:$OC$3,"<>"&List!$L$13)) -> 0 | G4: =IF('Project Follow up - Base'!$N20="",0, COUNTIFS('Project Follow up - Base'!$AC20:$OC20,"<="&10,'Project Follow up - Base'!$AC20:$OC20,">="&-10,'Project Follow up - Base'!$AC$3:$OC$3,">="&DATE(YEAR(G$3),MONTH(G$3),1),'Project Follow up - Base'!$AC$3:$OC$3,"<="&(DATE(YEAR(G$3),MONTH(G$3)+1,1)-1),'Project Follow up - Base'!$AC$4:$OC$4,"<>"&"Fri",'Project Follow up - Base'!$AC$4:$OC$4,"<>"&"Sat",'Project Follow up - Base'!$AC$3:$OC$3,"<>"&List!$L$3,'Project Follow up - Base'!$AC$3:$OC$3,"<>"&List!$L$4,'Project Follow up - Base'!$AC$3:$OC$3,"<>"&List!$L$5,'Project Follow up - Base'!$AC$3:$OC$3,"<>"&List!$L$6,'Project Follow up - Base'!$AC$3:$OC$3,"<>"&List!$L$7,'Project Follow up - Base'!$AC$3:$OC$3,"<>"&List!$L$8,'Project Follow up - Base'!$AC$3:$OC$3,"<>"&List!$L$9,'Project Follow up - Base'!$AC$3:$OC$3,"<>"&List!$L$10,'Project Follow up - Base'!$AC$3:$OC$3,"<>"&List!$L$11,'Project Follow up - Base'!$AC$3:$OC$3,"<>"&List!$L$12,'Project Follow up - Base'!$AC$3:$OC$3,"<>"&List!$L$13)) -> 0 | H4: =IF('Project Follow up - Base'!$N20="",0, COUNTIFS('Project Follow up - Base'!$AC20:$OC20,"<="&10,'Project Follow up - Base'!$AC20:$OC20,">="&-10,'Project Follow up - Base'!$AC$3:$OC$3,">="&DATE(YEAR(H$3),MONTH(H$3),1),'Project Follow up - Base'!$AC$3:$OC$3,"<="&(DATE(YEAR(H$3),MONTH(H$3)+1,1)-1),'Project Follow up - Base'!$AC$4:$OC$4,"<>"&"Fri",'Project Follow up - Base'!$AC$4:$OC$4,"<>"&"Sat",'Project Follow up - Base'!$AC$3:$OC$3,"<>"&List!$L$3,'Project Follow up - Base'!$AC$3:$OC$3,"<>"&List!$L$4,'Project Follow up - Base'!$AC$3:$OC$3,"<>"&List!$L$5,'Project Follow up - Base'!$AC$3:$OC$3,"<>"&List!$L$6,'Project Follow up - Base'!$AC$3:$OC$3,"<>"&List!$L$7,'Project Follow up - Base'!$AC$3:$OC$3,"<>"&List!$L$8,'Project Follow up - Base'!$AC$3:$OC$3,"<>"&List!$L$9,'Project Follow up - Base'!$AC$3:$OC$3,"<>"&List!$L$10,'Project Follow up - Base'!$AC$3:$OC$3,"<>"&List!$L$11,'Project Follow up - Base'!$AC$3:$OC$3,"<>"&List!$L$12,'Project Follow up - Base'!$AC$3:$OC$3,"<>"&List!$L$13)) -> 0 | I4: =IF('Project Follow up - Base'!$N20="",0, COUNTIFS('Project Follow up - Base'!$AC20:$OC20,"<="&10,'Project Follow up - Base'!$AC20:$OC20,">="&-10,'Project Follow up - Base'!$AC$3:$OC$3,">="&DATE(YEAR(I$3),MONTH(I$3),1),'Project Follow up - Base'!$AC$3:$OC$3,"<="&(DATE(YEAR(I$3),MONTH(I$3)+1,1)-1),'Project Follow up - Base'!$AC$4:$OC$4,"<>"&"Fri",'Project Follow up - Base'!$AC$4:$OC$4,"<>"&"Sat",'Project Follow up - Base'!$AC$3:$OC$3,"<>"&List!$L$3,'Project Follow up - Base'!$AC$3:$OC$3,"<>"&List!$L$4,'Project Follow up - Base'!$AC$3:$OC$3,"<>"&List!$L$5,'Project Follow up - Base'!$AC$3:$OC$3,"<>"&List!$L$6,'Project Follow up - Base'!$AC$3:$OC$3,"<>"&List!$L$7,'Project Follow up - Base'!$AC$3:$OC$3,"<>"&List!$L$8,'Project Follow up - Base'!$AC$3:$OC$3,"<>"&List!$L$9,'Project Follow up - Base'!$AC$3:$OC$3,"<>"&List!$L$10,'Project Follow up - Base'!$AC$3:$OC$3,"<>"&List!$L$11,'Project Follow up - Base'!$AC$3:$OC$3,"<>"&List!$L$12,'Project Follow up - Base'!$AC$3:$OC$3,"<>"&List!$L$13)) -> 0 | J4: =IF('Project Follow up - Base'!$N20="",0, COUNTIFS('Project Follow up - Base'!$AC20:$OC20,"<="&10,'Project Follow up - Base'!$AC20:$OC20,">="&-10,'Project Follow up - Base'!$AC$3:$OC$3,">="&DATE(YEAR(J$3),MONTH(J$3),1),'Project Follow up - Base'!$AC$3:$OC$3,"<="&(DATE(YEAR(J$3),MONTH(J$3)+1,1)-1),'Project Follow up - Base'!$AC$4:$OC$4,"<>"&"Fri",'Project Follow up - Base'!$AC$4:$OC$4,"<>"&"Sat",'Project Follow up - Base'!$AC$3:$OC$3,"<>"&List!$L$3,'Project Follow up - Base'!$AC$3:$OC$3,"<>"&List!$L$4,'Project Follow up - Base'!$AC$3:$OC$3,"<>"&List!$L$5,'Project Follow up - Base'!$AC$3:$OC$3,"<>"&List!$L$6,'Project Follow up - Base'!$AC$3:$OC$3,"<>"&List!$L$7,'Project Follow up - Base'!$AC$3:$OC$3,"<>"&List!$L$8,'Project Follow up - Base'!$AC$3:$OC$3,"<>"&List!$L$9,'Project Follow up - Base'!$AC$3:$OC$3,"<>"&List!$L$10,'Project Follow up - Base'!$AC$3:$OC$3,"<>"&List!$L$11,'Project Follow up - Base'!$AC$3:$OC$3,"<>"&List!$L$12,'Project Follow up - Base'!$AC$3:$OC$3,"<>"&List!$L$13)) -> 0 | ... AL4: =IF('Project Follow up - Base'!$N20="",0, COUNTIFS('Project Follow up - Base'!$AC20:$OC20,"<="&10,'Project Follow up - Base'!$AC20:$OC20,">="&-10,'Project Follow up - Base'!$AC$3:$OC$3,">="&DATE(YEAR(AL$3),MONTH(AL$3),1),'Project Follow up - Base'!$AC$3:$OC$3,"<="&(DATE(YEAR(AL$3),MONTH(AL$3)+1,1)-1),'Project Follow up - Base'!$AC$4:$OC$4,"<>"&"Fri",'Project Follow up - Base'!$AC$4:$OC$4,"<>"&"Sat",'Project Follow up - Base'!$AC$3:$OC$3,"<>"&List!$L$3,'Project Follow up - Base'!$AC$3:$OC$3,"<>"&List!$L$4,'Project Follow up - Base'!$AC$3:$OC$3,"<>"&List!$L$5,'Project Follow up - Base'!$AC$3:$OC$3,"<>"&List!$L$6,'Project Follow up - Base'!$AC$3:$OC$3,"<>"&List!$L$7,'Project Follow up - Base'!$AC$3:$OC$3,"<>"&List!$L$8,'Project Follow up - Base'!$AC$3:$OC$3,"<>"&List!$L$9,'Project Follow up - Base'!$AC$3:$OC$3,"<>"&List!$L$10,'Project Follow up - Base'!$AC$3:$OC$3,"<>"&List!$L$11,'Project Follow up - Base'!$AC$3:$OC$3,"<>"&List!$L$12,'Project Follow up - Base'!$AC$3:$OC$3,"<>"&List!$L$13)) -> 0
A5: ='Project Follow up - Base'!$B$17 -> Studies | B5: ='Project Follow up - Base'!F21 | C5: =IF('Project Follow up - Base'!$N21="",0, COUNTIFS('Project Follow up - Base'!$AC21:$OC21,"<="&10,'Project Follow up - Base'!$AC21:$OC21,">="&-10,'Project Follow up - Base'!$AC$3:$OC$3,">="&DATE(YEAR(C$3),MONTH(C$3),1),'Project Follow up - Base'!$AC$3:$OC$3,"<="&(DATE(YEAR(C$3),MONTH(C$3)+1,1)-1),'Project Follow up - Base'!$AC$4:$OC$4,"<>"&"Fri",'Project Follow up - Base'!$AC$4:$OC$4,"<>"&"Sat",'Project Follow up - Base'!$AC$3:$OC$3,"<>"&List!$L$3,'Project Follow up - Base'!$AC$3:$OC$3,"<>"&List!$L$4,'Project Follow up - Base'!$AC$3:$OC$3,"<>"&List!$L$5,'Project Follow up - Base'!$AC$3:$OC$3,"<>"&List!$L$6,'Project Follow up - Base'!$AC$3:$OC$3,"<>"&List!$L$7,'Project Follow up - Base'!$AC$3:$OC$3,"<>"&List!$L$8,'Project Follow up - Base'!$AC$3:$OC$3,"<>"&List!$L$9,'Project Follow up - Base'!$AC$3:$OC$3,"<>"&List!$L$10,'Project Follow up - Base'!$AC$3:$OC$3,"<>"&List!$L$11,'Project Follow up - Base'!$AC$3:$OC$3,"<>"&List!$L$12,'Project Follow up - Base'!$AC$3:$OC$3,"<>"&List!$L$13)) -> 0 | D5: =IF('Project Follow up - Base'!$N21="",0, COUNTIFS('Project Follow up - Base'!$AC21:$OC21,"<="&10,'Project Follow up - Base'!$AC21:$OC21,">="&-10,'Project Follow up - Base'!$AC$3:$OC$3,">="&DATE(YEAR(D$3),MONTH(D$3),1),'Project Follow up - Base'!$AC$3:$OC$3,"<="&(DATE(YEAR(D$3),MONTH(D$3)+1,1)-1),'Project Follow up - Base'!$AC$4:$OC$4,"<>"&"Fri",'Project Follow up - Base'!$AC$4:$OC$4,"<>"&"Sat",'Project Follow up - Base'!$AC$3:$OC$3,"<>"&List!$L$3,'Project Follow up - Base'!$AC$3:$OC$3,"<>"&List!$L$4,'Project Follow up - Base'!$AC$3:$OC$3,"<>"&List!$L$5,'Project Follow up - Base'!$AC$3:$OC$3,"<>"&List!$L$6,'Project Follow up - Base'!$AC$3:$OC$3,"<>"&List!$L$7,'Project Follow up - Base'!$AC$3:$OC$3,"<>"&List!$L$8,'Project Follow up - Base'!$AC$3:$OC$3,"<>"&List!$L$9,'Project Follow up - Base'!$AC$3:$OC$3,"<>"&List!$L$10,'Project Follow up - Base'!$AC$3:$OC$3,"<>"&List!$L$11,'Project Follow up - Base'!$AC$3:$OC$3,"<>"&List!$L$12,'Project Follow up - Base'!$AC$3:$OC$3,"<>"&List!$L$13)) -> 0 | E5: =IF('Project Follow up - Base'!$N21="",0, COUNTIFS('Project Follow up - Base'!$AC21:$OC21,"<="&10,'Project Follow up - Base'!$AC21:$OC21,">="&-10,'Project Follow up - Base'!$AC$3:$OC$3,">="&DATE(YEAR(E$3),MONTH(E$3),1),'Project Follow up - Base'!$AC$3:$OC$3,"<="&(DATE(YEAR(E$3),MONTH(E$3)+1,1)-1),'Project Follow up - Base'!$AC$4:$OC$4,"<>"&"Fri",'Project Follow up - Base'!$AC$4:$OC$4,"<>"&"Sat",'Project Follow up - Base'!$AC$3:$OC$3,"<>"&List!$L$3,'Project Follow up - Base'!$AC$3:$OC$3,"<>"&List!$L$4,'Project Follow up - Base'!$AC$3:$OC$3,"<>"&List!$L$5,'Project Follow up - Base'!$AC$3:$OC$3,"<>"&List!$L$6,'Project Follow up - Base'!$AC$3:$OC$3,"<>"&List!$L$7,'Project Follow up - Base'!$AC$3:$OC$3,"<>"&List!$L$8,'Project Follow up - Base'!$AC$3:$OC$3,"<>"&List!$L$9,'Project Follow up - Base'!$AC$3:$OC$3,"<>"&List!$L$10,'Project Follow up - Base'!$AC$3:$OC$3,"<>"&List!$L$11,'Project Follow up - Base'!$AC$3:$OC$3,"<>"&List!$L$12,'Project Follow up - Base'!$AC$3:$OC$3,"<>"&List!$L$13)) -> 1 | F5: =IF('Project Follow up - Base'!$N21="",0, COUNTIFS('Project Follow up - Base'!$AC21:$OC21,"<="&10,'Project Follow up - Base'!$AC21:$OC21,">="&-10,'Project Follow up - Base'!$AC$3:$OC$3,">="&DATE(YEAR(F$3),MONTH(F$3),1),'Project Follow up - Base'!$AC$3:$OC$3,"<="&(DATE(YEAR(F$3),MONTH(F$3)+1,1)-1),'Project Follow up - Base'!$AC$4:$OC$4,"<>"&"Fri",'Project Follow up - Base'!$AC$4:$OC$4,"<>"&"Sat",'Project Follow up - Base'!$AC$3:$OC$3,"<>"&List!$L$3,'Project Follow up - Base'!$AC$3:$OC$3,"<>"&List!$L$4,'Project Follow up - Base'!$AC$3:$OC$3,"<>"&List!$L$5,'Project Follow up - Base'!$AC$3:$OC$3,"<>"&List!$L$6,'Project Follow up - Base'!$AC$3:$OC$3,"<>"&List!$L$7,'Project Follow up - Base'!$AC$3:$OC$3,"<>"&List!$L$8,'Project Follow up - Base'!$AC$3:$OC$3,"<>"&List!$L$9,'Project Follow up - Base'!$AC$3:$OC$3,"<>"&List!$L$10,'Project Follow up - Base'!$AC$3:$OC$3,"<>"&List!$L$11,'Project Follow up - Base'!$AC$3:$OC$3,"<>"&List!$L$12,'Project Follow up - Base'!$AC$3:$OC$3,"<>"&List!$L$13)) -> 0 | G5: =IF('Project Follow up - Base'!$N21="",0, COUNTIFS('Project Follow up - Base'!$AC21:$OC21,"<="&10,'Project Follow up - Base'!$AC21:$OC21,">="&-10,'Project Follow up - Base'!$AC$3:$OC$3,">="&DATE(YEAR(G$3),MONTH(G$3),1),'Project Follow up - Base'!$AC$3:$OC$3,"<="&(DATE(YEAR(G$3),MONTH(G$3)+1,1)-1),'Project Follow up - Base'!$AC$4:$OC$4,"<>"&"Fri",'Project Follow up - Base'!$AC$4:$OC$4,"<>"&"Sat",'Project Follow up - Base'!$AC$3:$OC$3,"<>"&List!$L$3,'Project Follow up - Base'!$AC$3:$OC$3,"<>"&List!$L$4,'Project Follow up - Base'!$AC$3:$OC$3,"<>"&List!$L$5,'Project Follow up - Base'!$AC$3:$OC$3,"<>"&List!$L$6,'Project Follow up - Base'!$AC$3:$OC$3,"<>"&List!$L$7,'Project Follow up - Base'!$AC$3:$OC$3,"<>"&List!$L$8,'Project Follow up - Base'!$AC$3:$OC$3,"<>"&List!$L$9,'Project Follow up - Base'!$AC$3:$OC$3,"<>"&List!$L$10,'Project Follow up - Base'!$AC$3:$OC$3,"<>"&List!$L$11,'Project Follow up - Base'!$AC$3:$OC$3,"<>"&List!$L$12,'Project Follow up - Base'!$AC$3:$OC$3,"<>"&List!$L$13)) -> 0 | H5: =IF('Project Follow up - Base'!$N21="",0, COUNTIFS('Project Follow up - Base'!$AC21:$OC21,"<="&10,'Project Follow up - Base'!$AC21:$OC21,">="&-10,'Project Follow up - Base'!$AC$3:$OC$3,">="&DATE(YEAR(H$3),MONTH(H$3),1),'Project Follow up - Base'!$AC$3:$OC$3,"<="&(DATE(YEAR(H$3),MONTH(H$3)+1,1)-1),'Project Follow up - Base'!$AC$4:$OC$4,"<>"&"Fri",'Project Follow up - Base'!$AC$4:$OC$4,"<>"&"Sat",'Project Follow up - Base'!$AC$3:$OC$3,"<>"&List!$L$3,'Project Follow up - Base'!$AC$3:$OC$3,"<>"&List!$L$4,'Project Follow up - Base'!$AC$3:$OC$3,"<>"&List!$L$5,'Project Follow up - Base'!$AC$3:$OC$3,"<>"&List!$L$6,'Project Follow up - Base'!$AC$3:$OC$3,"<>"&List!$L$7,'Project Follow up - Base'!$AC$3:$OC$3,"<>"&List!$L$8,'Project Follow up - Base'!$AC$3:$OC$3,"<>"&List!$L$9,'Project Follow up - Base'!$AC$3:$OC$3,"<>"&List!$L$10,'Project Follow up - Base'!$AC$3:$OC$3,"<>"&List!$L$11,'Project Follow up - Base'!$AC$3:$OC$3,"<>"&List!$L$12,'Project Follow up - Base'!$AC$3:$OC$3,"<>"&List!$L$13)) -> 0 | I5: =IF('Project Follow up - Base'!$N21="",0, COUNTIFS('Project Follow up - Base'!$AC21:$OC21,"<="&10,'Project Follow up - Base'!$AC21:$OC21,">="&-10,'Project Follow up - Base'!$AC$3:$OC$3,">="&DATE(YEAR(I$3),MONTH(I$3),1),'Project Follow up - Base'!$AC$3:$OC$3,"<="&(DATE(YEAR(I$3),MONTH(I$3)+1,1)-1),'Project Follow up - Base'!$AC$4:$OC$4,"<>"&"Fri",'Project Follow up - Base'!$AC$4:$OC$4,"<>"&"Sat",'Project Follow up - Base'!$AC$3:$OC$3,"<>"&List!$L$3,'Project Follow up - Base'!$AC$3:$OC$3,"<>"&List!$L$4,'Project Follow up - Base'!$AC$3:$OC$3,"<>"&List!$L$5,'Project Follow up - Base'!$AC$3:$OC$3,"<>"&List!$L$6,'Project Follow up - Base'!$AC$3:$OC$3,"<>"&List!$L$7,'Project Follow up - Base'!$AC$3:$OC$3,"<>"&List!$L$8,'Project Follow up - Base'!$AC$3:$OC$3,"<>"&List!$L$9,'Project Follow up - Base'!$AC$3:$OC$3,"<>"&List!$L$10,'Project Follow up - Base'!$AC$3:$OC$3,"<>"&List!$L$11,'Project Follow up - Base'!$AC$3:$OC$3,"<>"&List!$L$12,'Project Follow up - Base'!$AC$3:$OC$3,"<>"&List!$L$13)) -> 0 | J5: =IF('Project Follow up - Base'!$N21="",0, COUNTIFS('Project Follow up - Base'!$AC21:$OC21,"<="&10,'Project Follow up - Base'!$AC21:$OC21,">="&-10,'Project Follow up - Base'!$AC$3:$OC$3,">="&DATE(YEAR(J$3),MONTH(J$3),1),'Project Follow up - Base'!$AC$3:$OC$3,"<="&(DATE(YEAR(J$3),MONTH(J$3)+1,1)-1),'Project Follow up - Base'!$AC$4:$OC$4,"<>"&"Fri",'Project Follow up - Base'!$AC$4:$OC$4,"<>"&"Sat",'Project Follow up - Base'!$AC$3:$OC$3,"<>"&List!$L$3,'Project Follow up - Base'!$AC$3:$OC$3,"<>"&List!$L$4,'Project Follow up - Base'!$AC$3:$OC$3,"<>"&List!$L$5,'Project Follow up - Base'!$AC$3:$OC$3,"<>"&List!$L$6,'Project Follow up - Base'!$AC$3:$OC$3,"<>"&List!$L$7,'Project Follow up - Base'!$AC$3:$OC$3,"<>"&List!$L$8,'Project Follow up - Base'!$AC$3:$OC$3,"<>"&List!$L$9,'Project Follow up - Base'!$AC$3:$OC$3,"<>"&List!$L$10,'Project Follow up - Base'!$AC$3:$OC$3,"<>"&List!$L$11,'Project Follow up - Base'!$AC$3:$OC$3,"<>"&List!$L$12,'Project Follow up - Base'!$AC$3:$OC$3,"<>"&List!$L$13)) -> 0 | ... AL5: =IF('Project Follow up - Base'!$N21="",0, COUNTIFS('Project Follow up - Base'!$AC21:$OC21,"<="&10,'Project Follow up - Base'!$AC21:$OC21,">="&-10,'Project Follow up - Base'!$AC$3:$OC$3,">="&DATE(YEAR(AL$3),MONTH(AL$3),1),'Project Follow up - Base'!$AC$3:$OC$3,"<="&(DATE(YEAR(AL$3),MONTH(AL$3)+1,1)-1),'Project Follow up - Base'!$AC$4:$OC$4,"<>"&"Fri",'Project Follow up - Base'!$AC$4:$OC$4,"<>"&"Sat",'Project Follow up - Base'!$AC$3:$OC$3,"<>"&List!$L$3,'Project Follow up - Base'!$AC$3:$OC$3,"<>"&List!$L$4,'Project Follow up - Base'!$AC$3:$OC$3,"<>"&List!$L$5,'Project Follow up - Base'!$AC$3:$OC$3,"<>"&List!$L$6,'Project Follow up - Base'!$AC$3:$OC$3,"<>"&List!$L$7,'Project Follow up - Base'!$AC$3:$OC$3,"<>"&List!$L$8,'Project Follow up - Base'!$AC$3:$OC$3,"<>"&List!$L$9,'Project Follow up - Base'!$AC$3:$OC$3,"<>"&List!$L$10,'Project Follow up - Base'!$AC$3:$OC$3,"<>"&List!$L$11,'Project Follow up - Base'!$AC$3:$OC$3,"<>"&List!$L$12,'Project Follow up - Base'!$AC$3:$OC$3,"<>"&List!$L$13)) -> 0
A6: ='Project Follow up - Base'!$B$17 -> Studies | B6: ='Project Follow up - Base'!F22 -> Abdulrahman Bukees | C6: =IF('Project Follow up - Base'!$N22="",0, COUNTIFS('Project Follow up - Base'!$AC22:$OC22,"<="&10,'Project Follow up - Base'!$AC22:$OC22,">="&-10,'Project Follow up - Base'!$AC$3:$OC$3,">="&DATE(YEAR(C$3),MONTH(C$3),1),'Project Follow up - Base'!$AC$3:$OC$3,"<="&(DATE(YEAR(C$3),MONTH(C$3)+1,1)-1),'Project Follow up - Base'!$AC$4:$OC$4,"<>"&"Fri",'Project Follow up - Base'!$AC$4:$OC$4,"<>"&"Sat",'Project Follow up - Base'!$AC$3:$OC$3,"<>"&List!$L$3,'Project Follow up - Base'!$AC$3:$OC$3,"<>"&List!$L$4,'Project Follow up - Base'!$AC$3:$OC$3,"<>"&List!$L$5,'Project Follow up - Base'!$AC$3:$OC$3,"<>"&List!$L$6,'Project Follow up - Base'!$AC$3:$OC$3,"<>"&List!$L$7,'Project Follow up - Base'!$AC$3:$OC$3,"<>"&List!$L$8,'Project Follow up - Base'!$AC$3:$OC$3,"<>"&List!$L$9,'Project Follow up - Base'!$AC$3:$OC$3,"<>"&List!$L$10,'Project Follow up - Base'!$AC$3:$OC$3,"<>"&List!$L$11,'Project Follow up - Base'!$AC$3:$OC$3,"<>"&List!$L$12,'Project Follow up - Base'!$AC$3:$OC$3,"<>"&List!$L$13)) -> 0 | D6: =IF('Project Follow up - Base'!$N22="",0, COUNTIFS('Project Follow up - Base'!$AC22:$OC22,"<="&10,'Project Follow up - Base'!$AC22:$OC22,">="&-10,'Project Follow up - Base'!$AC$3:$OC$3,">="&DATE(YEAR(D$3),MONTH(D$3),1),'Project Follow up - Base'!$AC$3:$OC$3,"<="&(DATE(YEAR(D$3),MONTH(D$3)+1,1)-1),'Project Follow up - Base'!$AC$4:$OC$4,"<>"&"Fri",'Project Follow up - Base'!$AC$4:$OC$4,"<>"&"Sat",'Project Follow up - Base'!$AC$3:$OC$3,"<>"&List!$L$3,'Project Follow up - Base'!$AC$3:$OC$3,"<>"&List!$L$4,'Project Follow up - Base'!$AC$3:$OC$3,"<>"&List!$L$5,'Project Follow up - Base'!$AC$3:$OC$3,"<>"&List!$L$6,'Project Follow up - Base'!$AC$3:$OC$3,"<>"&List!$L$7,'Project Follow up - Base'!$AC$3:$OC$3,"<>"&List!$L$8,'Project Follow up - Base'!$AC$3:$OC$3,"<>"&List!$L$9,'Project Follow up - Base'!$AC$3:$OC$3,"<>"&List!$L$10,'Project Follow up - Base'!$AC$3:$OC$3,"<>"&List!$L$11,'Project Follow up - Base'!$AC$3:$OC$3,"<>"&List!$L$12,'Project Follow up - Base'!$AC$3:$OC$3,"<>"&List!$L$13)) -> 0 | E6: =IF('Project Follow up - Base'!$N22="",0, COUNTIFS('Project Follow up - Base'!$AC22:$OC22,"<="&10,'Project Follow up - Base'!$AC22:$OC22,">="&-10,'Project Follow up - Base'!$AC$3:$OC$3,">="&DATE(YEAR(E$3),MONTH(E$3),1),'Project Follow up - Base'!$AC$3:$OC$3,"<="&(DATE(YEAR(E$3),MONTH(E$3)+1,1)-1),'Project Follow up - Base'!$AC$4:$OC$4,"<>"&"Fri",'Project Follow up - Base'!$AC$4:$OC$4,"<>"&"Sat",'Project Follow up - Base'!$AC$3:$OC$3,"<>"&List!$L$3,'Project Follow up - Base'!$AC$3:$OC$3,"<>"&List!$L$4,'Project Follow up - Base'!$AC$3:$OC$3,"<>"&List!$L$5,'Project Follow up - Base'!$AC$3:$OC$3,"<>"&List!$L$6,'Project Follow up - Base'!$AC$3:$OC$3,"<>"&List!$L$7,'Project Follow up - Base'!$AC$3:$OC$3,"<>"&List!$L$8,'Project Follow up - Base'!$AC$3:$OC$3,"<>"&List!$L$9,'Project Follow up - Base'!$AC$3:$OC$3,"<>"&List!$L$10,'Project Follow up - Base'!$AC$3:$OC$3,"<>"&List!$L$11,'Project Follow up - Base'!$AC$3:$OC$3,"<>"&List!$L$12,'Project Follow up - Base'!$AC$3:$OC$3,"<>"&List!$L$13)) -> 6 | F6: =IF('Project Follow up - Base'!$N22="",0, COUNTIFS('Project Follow up - Base'!$AC22:$OC22,"<="&10,'Project Follow up - Base'!$AC22:$OC22,">="&-10,'Project Follow up - Base'!$AC$3:$OC$3,">="&DATE(YEAR(F$3),MONTH(F$3),1),'Project Follow up - Base'!$AC$3:$OC$3,"<="&(DATE(YEAR(F$3),MONTH(F$3)+1,1)-1),'Project Follow up - Base'!$AC$4:$OC$4,"<>"&"Fri",'Project Follow up - Base'!$AC$4:$OC$4,"<>"&"Sat",'Project Follow up - Base'!$AC$3:$OC$3,"<>"&List!$L$3,'Project Follow up - Base'!$AC$3:$OC$3,"<>"&List!$L$4,'Project Follow up - Base'!$AC$3:$OC$3,"<>"&List!$L$5,'Project Follow up - Base'!$AC$3:$OC$3,"<>"&List!$L$6,'Project Follow up - Base'!$AC$3:$OC$3,"<>"&List!$L$7,'Project Follow up - Base'!$AC$3:$OC$3,"<>"&List!$L$8,'Project Follow up - Base'!$AC$3:$OC$3,"<>"&List!$L$9,'Project Follow up - Base'!$AC$3:$OC$3,"<>"&List!$L$10,'Project Follow up - Base'!$AC$3:$OC$3,"<>"&List!$L$11,'Project Follow up - Base'!$AC$3:$OC$3,"<>"&List!$L$12,'Project Follow up - Base'!$AC$3:$OC$3,"<>"&List!$L$13)) -> 0 | G6: =IF('Project Follow up - Base'!$N22="",0, COUNTIFS('Project Follow up - Base'!$AC22:$OC22,"<="&10,'Project Follow up - Base'!$AC22:$OC22,">="&-10,'Project Follow up - Base'!$AC$3:$OC$3,">="&DATE(YEAR(G$3),MONTH(G$3),1),'Project Follow up - Base'!$AC$3:$OC$3,"<="&(DATE(YEAR(G$3),MONTH(G$3)+1,1)-1),'Project Follow up - Base'!$AC$4:$OC$4,"<>"&"Fri",'Project Follow up - Base'!$AC$4:$OC$4,"<>"&"Sat",'Project Follow up - Base'!$AC$3:$OC$3,"<>"&List!$L$3,'Project Follow up - Base'!$AC$3:$OC$3,"<>"&List!$L$4,'Project Follow up - Base'!$AC$3:$OC$3,"<>"&List!$L$5,'Project Follow up - Base'!$AC$3:$OC$3,"<>"&List!$L$6,'Project Follow up - Base'!$AC$3:$OC$3,"<>"&List!$L$7,'Project Follow up - Base'!$AC$3:$OC$3,"<>"&List!$L$8,'Project Follow up - Base'!$AC$3:$OC$3,"<>"&List!$L$9,'Project Follow up - Base'!$AC$3:$OC$3,"<>"&List!$L$10,'Project Follow up - Base'!$AC$3:$OC$3,"<>"&List!$L$11,'Project Follow up - Base'!$AC$3:$OC$3,"<>"&List!$L$12,'Project Follow up - Base'!$AC$3:$OC$3,"<>"&List!$L$13)) -> 0 | H6: =IF('Project Follow up - Base'!$N22="",0, COUNTIFS('Project Follow up - Base'!$AC22:$OC22,"<="&10,'Project Follow up - Base'!$AC22:$OC22,">="&-10,'Project Follow up - Base'!$AC$3:$OC$3,">="&DATE(YEAR(H$3),MONTH(H$3),1),'Project Follow up - Base'!$AC$3:$OC$3,"<="&(DATE(YEAR(H$3),MONTH(H$3)+1,1)-1),'Project Follow up - Base'!$AC$4:$OC$4,"<>"&"Fri",'Project Follow up - Base'!$AC$4:$OC$4,"<>"&"Sat",'Project Follow up - Base'!$AC$3:$OC$3,"<>"&List!$L$3,'Project Follow up - Base'!$AC$3:$OC$3,"<>"&List!$L$4,'Project Follow up - Base'!$AC$3:$OC$3,"<>"&List!$L$5,'Project Follow up - Base'!$AC$3:$OC$3,"<>"&List!$L$6,'Project Follow up - Base'!$AC$3:$OC$3,"<>"&List!$L$7,'Project Follow up - Base'!$AC$3:$OC$3,"<>"&List!$L$8,'Project Follow up - Base'!$AC$3:$OC$3,"<>"&List!$L$9,'Project Follow up - Base'!$AC$3:$OC$3,"<>"&List!$L$10,'Project Follow up - Base'!$AC$3:$OC$3,"<>"&List!$L$11,'Project Follow up - Base'!$AC$3:$OC$3,"<>"&List!$L$12,'Project Follow up - Base'!$AC$3:$OC$3,"<>"&List!$L$13)) -> 0 | I6: =IF('Project Follow up - Base'!$N22="",0, COUNTIFS('Project Follow up - Base'!$AC22:$OC22,"<="&10,'Project Follow up - Base'!$AC22:$OC22,">="&-10,'Project Follow up - Base'!$AC$3:$OC$3,">="&DATE(YEAR(I$3),MONTH(I$3),1),'Project Follow up - Base'!$AC$3:$OC$3,"<="&(DATE(YEAR(I$3),MONTH(I$3)+1,1)-1),'Project Follow up - Base'!$AC$4:$OC$4,"<>"&"Fri",'Project Follow up - Base'!$AC$4:$OC$4,"<>"&"Sat",'Project Follow up - Base'!$AC$3:$OC$3,"<>"&List!$L$3,'Project Follow up - Base'!$AC$3:$OC$3,"<>"&List!$L$4,'Project Follow up - Base'!$AC$3:$OC$3,"<>"&List!$L$5,'Project Follow up - Base'!$AC$3:$OC$3,"<>"&List!$L$6,'Project Follow up - Base'!$AC$3:$OC$3,"<>"&List!$L$7,'Project Follow up - Base'!$AC$3:$OC$3,"<>"&List!$L$8,'Project Follow up - Base'!$AC$3:$OC$3,"<>"&List!$L$9,'Project Follow up - Base'!$AC$3:$OC$3,"<>"&List!$L$10,'Project Follow up - Base'!$AC$3:$OC$3,"<>"&List!$L$11,'Project Follow up - Base'!$AC$3:$OC$3,"<>"&List!$L$12,'Project Follow up - Base'!$AC$3:$OC$3,"<>"&List!$L$13)) -> 0 | J6: =IF('Project Follow up - Base'!$N22="",0, COUNTIFS('Project Follow up - Base'!$AC22:$OC22,"<="&10,'Project Follow up - Base'!$AC22:$OC22,">="&-10,'Project Follow up - Base'!$AC$3:$OC$3,">="&DATE(YEAR(J$3),MONTH(J$3),1),'Project Follow up - Base'!$AC$3:$OC$3,"<="&(DATE(YEAR(J$3),MONTH(J$3)+1,1)-1),'Project Follow up - Base'!$AC$4:$OC$4,"<>"&"Fri",'Project Follow up - Base'!$AC$4:$OC$4,"<>"&"Sat",'Project Follow up - Base'!$AC$3:$OC$3,"<>"&List!$L$3,'Project Follow up - Base'!$AC$3:$OC$3,"<>"&List!$L$4,'Project Follow up - Base'!$AC$3:$OC$3,"<>"&List!$L$5,'Project Follow up - Base'!$AC$3:$OC$3,"<>"&List!$L$6,'Project Follow up - Base'!$AC$3:$OC$3,"<>"&List!$L$7,'Project Follow up - Base'!$AC$3:$OC$3,"<>"&List!$L$8,'Project Follow up - Base'!$AC$3:$OC$3,"<>"&List!$L$9,'Project Follow up - Base'!$AC$3:$OC$3,"<>"&List!$L$10,'Project Follow up - Base'!$AC$3:$OC$3,"<>"&List!$L$11,'Project Follow up - Base'!$AC$3:$OC$3,"<>"&List!$L$12,'Project Follow up - Base'!$AC$3:$OC$3,"<>"&List!$L$13)) -> 0 | ... AL6: =IF('Project Follow up - Base'!$N22="",0, COUNTIFS('Project Follow up - Base'!$AC22:$OC22,"<="&10,'Project Follow up - Base'!$AC22:$OC22,">="&-10,'Project Follow up - Base'!$AC$3:$OC$3,">="&DATE(YEAR(AL$3),MONTH(AL$3),1),'Project Follow up - Base'!$AC$3:$OC$3,"<="&(DATE(YEAR(AL$3),MONTH(AL$3)+1,1)-1),'Project Follow up - Base'!$AC$4:$OC$4,"<>"&"Fri",'Project Follow up - Base'!$AC$4:$OC$4,"<>"&"Sat",'Project Follow up - Base'!$AC$3:$OC$3,"<>"&List!$L$3,'Project Follow up - Base'!$AC$3:$OC$3,"<>"&List!$L$4,'Project Follow up - Base'!$AC$3:$OC$3,"<>"&List!$L$5,'Project Follow up - Base'!$AC$3:$OC$3,"<>"&List!$L$6,'Project Follow up - Base'!$AC$3:$OC$3,"<>"&List!$L$7,'Project Follow up - Base'!$AC$3:$OC$3,"<>"&List!$L$8,'Project Follow up - Base'!$AC$3:$OC$3,"<>"&List!$L$9,'Project Follow up - Base'!$AC$3:$OC$3,"<>"&List!$L$10,'Project Follow up - Base'!$AC$3:$OC$3,"<>"&List!$L$11,'Project Follow up - Base'!$AC$3:$OC$3,"<>"&List!$L$12,'Project Follow up - Base'!$AC$3:$OC$3,"<>"&List!$L$13)) -> 0
A7: ='Project Follow up - Base'!$B$17 -> Studies | B7: ='Project Follow up - Base'!F23 | C7: =IF('Project Follow up - Base'!$N23="",0, COUNTIFS('Project Follow up - Base'!$AC23:$OC23,"<="&10,'Project Follow up - Base'!$AC23:$OC23,">="&-10,'Project Follow up - Base'!$AC$3:$OC$3,">="&DATE(YEAR(C$3),MONTH(C$3),1),'Project Follow up - Base'!$AC$3:$OC$3,"<="&(DATE(YEAR(C$3),MONTH(C$3)+1,1)-1),'Project Follow up - Base'!$AC$4:$OC$4,"<>"&"Fri",'Project Follow up - Base'!$AC$4:$OC$4,"<>"&"Sat",'Project Follow up - Base'!$AC$3:$OC$3,"<>"&List!$L$3,'Project Follow up - Base'!$AC$3:$OC$3,"<>"&List!$L$4,'Project Follow up - Base'!$AC$3:$OC$3,"<>"&List!$L$5,'Project Follow up - Base'!$AC$3:$OC$3,"<>"&List!$L$6,'Project Follow up - Base'!$AC$3:$OC$3,"<>"&List!$L$7,'Project Follow up - Base'!$AC$3:$OC$3,"<>"&List!$L$8,'Project Follow up - Base'!$AC$3:$OC$3,"<>"&List!$L$9,'Project Follow up - Base'!$AC$3:$OC$3,"<>"&List!$L$10,'Project Follow up - Base'!$AC$3:$OC$3,"<>"&List!$L$11,'Project Follow up - Base'!$AC$3:$OC$3,"<>"&List!$L$12,'Project Follow up - Base'!$AC$3:$OC$3,"<>"&List!$L$13)) -> 0 | D7: =IF('Project Follow up - Base'!$N23="",0, COUNTIFS('Project Follow up - Base'!$AC23:$OC23,"<="&10,'Project Follow up - Base'!$AC23:$OC23,">="&-10,'Project Follow up - Base'!$AC$3:$OC$3,">="&DATE(YEAR(D$3),MONTH(D$3),1),'Project Follow up - Base'!$AC$3:$OC$3,"<="&(DATE(YEAR(D$3),MONTH(D$3)+1,1)-1),'Project Follow up - Base'!$AC$4:$OC$4,"<>"&"Fri",'Project Follow up - Base'!$AC$4:$OC$4,"<>"&"Sat",'Project Follow up - Base'!$AC$3:$OC$3,"<>"&List!$L$3,'Project Follow up - Base'!$AC$3:$OC$3,"<>"&List!$L$4,'Project Follow up - Base'!$AC$3:$OC$3,"<>"&List!$L$5,'Project Follow up - Base'!$AC$3:$OC$3,"<>"&List!$L$6,'Project Follow up - Base'!$AC$3:$OC$3,"<>"&List!$L$7,'Project Follow up - Base'!$AC$3:$OC$3,"<>"&List!$L$8,'Project Follow up - Base'!$AC$3:$OC$3,"<>"&List!$L$9,'Project Follow up - Base'!$AC$3:$OC$3,"<>"&List!$L$10,'Project Follow up - Base'!$AC$3:$OC$3,"<>"&List!$L$11,'Project Follow up - Base'!$AC$3:$OC$3,"<>"&List!$L$12,'Project Follow up - Base'!$AC$3:$OC$3,"<>"&List!$L$13)) -> 0 | E7: =IF('Project Follow up - Base'!$N23="",0, COUNTIFS('Project Follow up - Base'!$AC23:$OC23,"<="&10,'Project Follow up - Base'!$AC23:$OC23,">="&-10,'Project Follow up - Base'!$AC$3:$OC$3,">="&DATE(YEAR(E$3),MONTH(E$3),1),'Project Follow up - Base'!$AC$3:$OC$3,"<="&(DATE(YEAR(E$3),MONTH(E$3)+1,1)-1),'Project Follow up - Base'!$AC$4:$OC$4,"<>"&"Fri",'Project Follow up - Base'!$AC$4:$OC$4,"<>"&"Sat",'Project Follow up - Base'!$AC$3:$OC$3,"<>"&List!$L$3,'Project Follow up - Base'!$AC$3:$OC$3,"<>"&List!$L$4,'Project Follow up - Base'!$AC$3:$OC$3,"<>"&List!$L$5,'Project Follow up - Base'!$AC$3:$OC$3,"<>"&List!$L$6,'Project Follow up - Base'!$AC$3:$OC$3,"<>"&List!$L$7,'Project Follow up - Base'!$AC$3:$OC$3,"<>"&List!$L$8,'Project Follow up - Base'!$AC$3:$OC$3,"<>"&List!$L$9,'Project Follow up - Base'!$AC$3:$OC$3,"<>"&List!$L$10,'Project Follow up - Base'!$AC$3:$OC$3,"<>"&List!$L$11,'Project Follow up - Base'!$AC$3:$OC$3,"<>"&List!$L$12,'Project Follow up - Base'!$AC$3:$OC$3,"<>"&List!$L$13)) -> 1 | F7: =IF('Project Follow up - Base'!$N23="",0, COUNTIFS('Project Follow up - Base'!$AC23:$OC23,"<="&10,'Project Follow up - Base'!$AC23:$OC23,">="&-10,'Project Follow up - Base'!$AC$3:$OC$3,">="&DATE(YEAR(F$3),MONTH(F$3),1),'Project Follow up - Base'!$AC$3:$OC$3,"<="&(DATE(YEAR(F$3),MONTH(F$3)+1,1)-1),'Project Follow up - Base'!$AC$4:$OC$4,"<>"&"Fri",'Project Follow up - Base'!$AC$4:$OC$4,"<>"&"Sat",'Project Follow up - Base'!$AC$3:$OC$3,"<>"&List!$L$3,'Project Follow up - Base'!$AC$3:$OC$3,"<>"&List!$L$4,'Project Follow up - Base'!$AC$3:$OC$3,"<>"&List!$L$5,'Project Follow up - Base'!$AC$3:$OC$3,"<>"&List!$L$6,'Project Follow up - Base'!$AC$3:$OC$3,"<>"&List!$L$7,'Project Follow up - Base'!$AC$3:$OC$3,"<>"&List!$L$8,'Project Follow up - Base'!$AC$3:$OC$3,"<>"&List!$L$9,'Project Follow up - Base'!$AC$3:$OC$3,"<>"&List!$L$10,'Project Follow up - Base'!$AC$3:$OC$3,"<>"&List!$L$11,'Project Follow up - Base'!$AC$3:$OC$3,"<>"&List!$L$12,'Project Follow up - Base'!$AC$3:$OC$3,"<>"&List!$L$13)) -> 0 | G7: =IF('Project Follow up - Base'!$N23="",0, COUNTIFS('Project Follow up - Base'!$AC23:$OC23,"<="&10,'Project Follow up - Base'!$AC23:$OC23,">="&-10,'Project Follow up - Base'!$AC$3:$OC$3,">="&DATE(YEAR(G$3),MONTH(G$3),1),'Project Follow up - Base'!$AC$3:$OC$3,"<="&(DATE(YEAR(G$3),MONTH(G$3)+1,1)-1),'Project Follow up - Base'!$AC$4:$OC$4,"<>"&"Fri",'Project Follow up - Base'!$AC$4:$OC$4,"<>"&"Sat",'Project Follow up - Base'!$AC$3:$OC$3,"<>"&List!$L$3,'Project Follow up - Base'!$AC$3:$OC$3,"<>"&List!$L$4,'Project Follow up - Base'!$AC$3:$OC$3,"<>"&List!$L$5,'Project Follow up - Base'!$AC$3:$OC$3,"<>"&List!$L$6,'Project Follow up - Base'!$AC$3:$OC$3,"<>"&List!$L$7,'Project Follow up - Base'!$AC$3:$OC$3,"<>"&List!$L$8,'Project Follow up - Base'!$AC$3:$OC$3,"<>"&List!$L$9,'Project Follow up - Base'!$AC$3:$OC$3,"<>"&List!$L$10,'Project Follow up - Base'!$AC$3:$OC$3,"<>"&List!$L$11,'Project Follow up - Base'!$AC$3:$OC$3,"<>"&List!$L$12,'Project Follow up - Base'!$AC$3:$OC$3,"<>"&List!$L$13)) -> 0 | H7: =IF('Project Follow up - Base'!$N23="",0, COUNTIFS('Project Follow up - Base'!$AC23:$OC23,"<="&10,'Project Follow up - Base'!$AC23:$OC23,">="&-10,'Project Follow up - Base'!$AC$3:$OC$3,">="&DATE(YEAR(H$3),MONTH(H$3),1),'Project Follow up - Base'!$AC$3:$OC$3,"<="&(DATE(YEAR(H$3),MONTH(H$3)+1,1)-1),'Project Follow up - Base'!$AC$4:$OC$4,"<>"&"Fri",'Project Follow up - Base'!$AC$4:$OC$4,"<>"&"Sat",'Project Follow up - Base'!$AC$3:$OC$3,"<>"&List!$L$3,'Project Follow up - Base'!$AC$3:$OC$3,"<>"&List!$L$4,'Project Follow up - Base'!$AC$3:$OC$3,"<>"&List!$L$5,'Project Follow up - Base'!$AC$3:$OC$3,"<>"&List!$L$6,'Project Follow up - Base'!$AC$3:$OC$3,"<>"&List!$L$7,'Project Follow up - Base'!$AC$3:$OC$3,"<>"&List!$L$8,'Project Follow up - Base'!$AC$3:$OC$3,"<>"&List!$L$9,'Project Follow up - Base'!$AC$3:$OC$3,"<>"&List!$L$10,'Project Follow up - Base'!$AC$3:$OC$3,"<>"&List!$L$11,'Project Follow up - Base'!$AC$3:$OC$3,"<>"&List!$L$12,'Project Follow up - Base'!$AC$3:$OC$3,"<>"&List!$L$13)) -> 0 | I7: =IF('Project Follow up - Base'!$N23="",0, COUNTIFS('Project Follow up - Base'!$AC23:$OC23,"<="&10,'Project Follow up - Base'!$AC23:$OC23,">="&-10,'Project Follow up - Base'!$AC$3:$OC$3,">="&DATE(YEAR(I$3),MONTH(I$3),1),'Project Follow up - Base'!$AC$3:$OC$3,"<="&(DATE(YEAR(I$3),MONTH(I$3)+1,1)-1),'Project Follow up - Base'!$AC$4:$OC$4,"<>"&"Fri",'Project Follow up - Base'!$AC$4:$OC$4,"<>"&"Sat",'Project Follow up - Base'!$AC$3:$OC$3,"<>"&List!$L$3,'Project Follow up - Base'!$AC$3:$OC$3,"<>"&List!$L$4,'Project Follow up - Base'!$AC$3:$OC$3,"<>"&List!$L$5,'Project Follow up - Base'!$AC$3:$OC$3,"<>"&List!$L$6,'Project Follow up - Base'!$AC$3:$OC$3,"<>"&List!$L$7,'Project Follow up - Base'!$AC$3:$OC$3,"<>"&List!$L$8,'Project Follow up - Base'!$AC$3:$OC$3,"<>"&List!$L$9,'Project Follow up - Base'!$AC$3:$OC$3,"<>"&List!$L$10,'Project Follow up - Base'!$AC$3:$OC$3,"<>"&List!$L$11,'Project Follow up - Base'!$AC$3:$OC$3,"<>"&List!$L$12,'Project Follow up - Base'!$AC$3:$OC$3,"<>"&List!$L$13)) -> 0 | J7: =IF('Project Follow up - Base'!$N23="",0, COUNTIFS('Project Follow up - Base'!$AC23:$OC23,"<="&10,'Project Follow up - Base'!$AC23:$OC23,">="&-10,'Project Follow up - Base'!$AC$3:$OC$3,">="&DATE(YEAR(J$3),MONTH(J$3),1),'Project Follow up - Base'!$AC$3:$OC$3,"<="&(DATE(YEAR(J$3),MONTH(J$3)+1,1)-1),'Project Follow up - Base'!$AC$4:$OC$4,"<>"&"Fri",'Project Follow up - Base'!$AC$4:$OC$4,"<>"&"Sat",'Project Follow up - Base'!$AC$3:$OC$3,"<>"&List!$L$3,'Project Follow up - Base'!$AC$3:$OC$3,"<>"&List!$L$4,'Project Follow up - Base'!$AC$3:$OC$3,"<>"&List!$L$5,'Project Follow up - Base'!$AC$3:$OC$3,"<>"&List!$L$6,'Project Follow up - Base'!$AC$3:$OC$3,"<>"&List!$L$7,'Project Follow up - Base'!$AC$3:$OC$3,"<>"&List!$L$8,'Project Follow up - Base'!$AC$3:$OC$3,"<>"&List!$L$9,'Project Follow up - Base'!$AC$3:$OC$3,"<>"&List!$L$10,'Project Follow up - Base'!$AC$3:$OC$3,"<>"&List!$L$11,'Project Follow up - Base'!$AC$3:$OC$3,"<>"&List!$L$12,'Project Follow up - Base'!$AC$3:$OC$3,"<>"&List!$L$13)) -> 0 | ... AL7: =IF('Project Follow up - Base'!$N23="",0, COUNTIFS('Project Follow up - Base'!$AC23:$OC23,"<="&10,'Project Follow up - Base'!$AC23:$OC23,">="&-10,'Project Follow up - Base'!$AC$3:$OC$3,">="&DATE(YEAR(AL$3),MONTH(AL$3),1),'Project Follow up - Base'!$AC$3:$OC$3,"<="&(DATE(YEAR(AL$3),MONTH(AL$3)+1,1)-1),'Project Follow up - Base'!$AC$4:$OC$4,"<>"&"Fri",'Project Follow up - Base'!$AC$4:$OC$4,"<>"&"Sat",'Project Follow up - Base'!$AC$3:$OC$3,"<>"&List!$L$3,'Project Follow up - Base'!$AC$3:$OC$3,"<>"&List!$L$4,'Project Follow up - Base'!$AC$3:$OC$3,"<>"&List!$L$5,'Project Follow up - Base'!$AC$3:$OC$3,"<>"&List!$L$6,'Project Follow up - Base'!$AC$3:$OC$3,"<>"&List!$L$7,'Project Follow up - Base'!$AC$3:$OC$3,"<>"&List!$L$8,'Project Follow up - Base'!$AC$3:$OC$3,"<>"&List!$L$9,'Project Follow up - Base'!$AC$3:$OC$3,"<>"&List!$L$10,'Project Follow up - Base'!$AC$3:$OC$3,"<>"&List!$L$11,'Project Follow up - Base'!$AC$3:$OC$3,"<>"&List!$L$12,'Project Follow up - Base'!$AC$3:$OC$3,"<>"&List!$L$13)) -> 0
A8: ='Project Follow up - Base'!$B$17 -> Studies | B8: ='Project Follow up - Base'!F24 | C8: =IF('Project Follow up - Base'!$N24="",0, COUNTIFS('Project Follow up - Base'!$AC24:$OC24,"<="&10,'Project Follow up - Base'!$AC24:$OC24,">="&-10,'Project Follow up - Base'!$AC$3:$OC$3,">="&DATE(YEAR(C$3),MONTH(C$3),1),'Project Follow up - Base'!$AC$3:$OC$3,"<="&(DATE(YEAR(C$3),MONTH(C$3)+1,1)-1),'Project Follow up - Base'!$AC$4:$OC$4,"<>"&"Fri",'Project Follow up - Base'!$AC$4:$OC$4,"<>"&"Sat",'Project Follow up - Base'!$AC$3:$OC$3,"<>"&List!$L$3,'Project Follow up - Base'!$AC$3:$OC$3,"<>"&List!$L$4,'Project Follow up - Base'!$AC$3:$OC$3,"<>"&List!$L$5,'Project Follow up - Base'!$AC$3:$OC$3,"<>"&List!$L$6,'Project Follow up - Base'!$AC$3:$OC$3,"<>"&List!$L$7,'Project Follow up - Base'!$AC$3:$OC$3,"<>"&List!$L$8,'Project Follow up - Base'!$AC$3:$OC$3,"<>"&List!$L$9,'Project Follow up - Base'!$AC$3:$OC$3,"<>"&List!$L$10,'Project Follow up - Base'!$AC$3:$OC$3,"<>"&List!$L$11,'Project Follow up - Base'!$AC$3:$OC$3,"<>"&List!$L$12,'Project Follow up - Base'!$AC$3:$OC$3,"<>"&List!$L$13)) -> 0 | D8: =IF('Project Follow up - Base'!$N24="",0, COUNTIFS('Project Follow up - Base'!$AC24:$OC24,"<="&10,'Project Follow up - Base'!$AC24:$OC24,">="&-10,'Project Follow up - Base'!$AC$3:$OC$3,">="&DATE(YEAR(D$3),MONTH(D$3),1),'Project Follow up - Base'!$AC$3:$OC$3,"<="&(DATE(YEAR(D$3),MONTH(D$3)+1,1)-1),'Project Follow up - Base'!$AC$4:$OC$4,"<>"&"Fri",'Project Follow up - Base'!$AC$4:$OC$4,"<>"&"Sat",'Project Follow up - Base'!$AC$3:$OC$3,"<>"&List!$L$3,'Project Follow up - Base'!$AC$3:$OC$3,"<>"&List!$L$4,'Project Follow up - Base'!$AC$3:$OC$3,"<>"&List!$L$5,'Project Follow up - Base'!$AC$3:$OC$3,"<>"&List!$L$6,'Project Follow up - Base'!$AC$3:$OC$3,"<>"&List!$L$7,'Project Follow up - Base'!$AC$3:$OC$3,"<>"&List!$L$8,'Project Follow up - Base'!$AC$3:$OC$3,"<>"&List!$L$9,'Project Follow up - Base'!$AC$3:$OC$3,"<>"&List!$L$10,'Project Follow up - Base'!$AC$3:$OC$3,"<>"&List!$L$11,'Project Follow up - Base'!$AC$3:$OC$3,"<>"&List!$L$12,'Project Follow up - Base'!$AC$3:$OC$3,"<>"&List!$L$13)) -> 0 | E8: =IF('Project Follow up - Base'!$N24="",0, COUNTIFS('Project Follow up - Base'!$AC24:$OC24,"<="&10,'Project Follow up - Base'!$AC24:$OC24,">="&-10,'Project Follow up - Base'!$AC$3:$OC$3,">="&DATE(YEAR(E$3),MONTH(E$3),1),'Project Follow up - Base'!$AC$3:$OC$3,"<="&(DATE(YEAR(E$3),MONTH(E$3)+1,1)-1),'Project Follow up - Base'!$AC$4:$OC$4,"<>"&"Fri",'Project Follow up - Base'!$AC$4:$OC$4,"<>"&"Sat",'Project Follow up - Base'!$AC$3:$OC$3,"<>"&List!$L$3,'Project Follow up - Base'!$AC$3:$OC$3,"<>"&List!$L$4,'Project Follow up - Base'!$AC$3:$OC$3,"<>"&List!$L$5,'Project Follow up - Base'!$AC$3:$OC$3,"<>"&List!$L$6,'Project Follow up - Base'!$AC$3:$OC$3,"<>"&List!$L$7,'Project Follow up - Base'!$AC$3:$OC$3,"<>"&List!$L$8,'Project Follow up - Base'!$AC$3:$OC$3,"<>"&List!$L$9,'Project Follow up - Base'!$AC$3:$OC$3,"<>"&List!$L$10,'Project Follow up - Base'!$AC$3:$OC$3,"<>"&List!$L$11,'Project Follow up - Base'!$AC$3:$OC$3,"<>"&List!$L$12,'Project Follow up - Base'!$AC$3:$OC$3,"<>"&List!$L$13)) -> 0 | F8: =IF('Project Follow up - Base'!$N24="",0, COUNTIFS('Project Follow up - Base'!$AC24:$OC24,"<="&10,'Project Follow up - Base'!$AC24:$OC24,">="&-10,'Project Follow up - Base'!$AC$3:$OC$3,">="&DATE(YEAR(F$3),MONTH(F$3),1),'Project Follow up - Base'!$AC$3:$OC$3,"<="&(DATE(YEAR(F$3),MONTH(F$3)+1,1)-1),'Project Follow up - Base'!$AC$4:$OC$4,"<>"&"Fri",'Project Follow up - Base'!$AC$4:$OC$4,"<>"&"Sat",'Project Follow up - Base'!$AC$3:$OC$3,"<>"&List!$L$3,'Project Follow up - Base'!$AC$3:$OC$3,"<>"&List!$L$4,'Project Follow up - Base'!$AC$3:$OC$3,"<>"&List!$L$5,'Project Follow up - Base'!$AC$3:$OC$3,"<>"&List!$L$6,'Project Follow up - Base'!$AC$3:$OC$3,"<>"&List!$L$7,'Project Follow up - Base'!$AC$3:$OC$3,"<>"&List!$L$8,'Project Follow up - Base'!$AC$3:$OC$3,"<>"&List!$L$9,'Project Follow up - Base'!$AC$3:$OC$3,"<>"&List!$L$10,'Project Follow up - Base'!$AC$3:$OC$3,"<>"&List!$L$11,'Project Follow up - Base'!$AC$3:$OC$3,"<>"&List!$L$12,'Project Follow up - Base'!$AC$3:$OC$3,"<>"&List!$L$13)) -> 0 | G8: =IF('Project Follow up - Base'!$N24="",0, COUNTIFS('Project Follow up - Base'!$AC24:$OC24,"<="&10,'Project Follow up - Base'!$AC24:$OC24,">="&-10,'Project Follow up - Base'!$AC$3:$OC$3,">="&DATE(YEAR(G$3),MONTH(G$3),1),'Project Follow up - Base'!$AC$3:$OC$3,"<="&(DATE(YEAR(G$3),MONTH(G$3)+1,1)-1),'Project Follow up - Base'!$AC$4:$OC$4,"<>"&"Fri",'Project Follow up - Base'!$AC$4:$OC$4,"<>"&"Sat",'Project Follow up - Base'!$AC$3:$OC$3,"<>"&List!$L$3,'Project Follow up - Base'!$AC$3:$OC$3,"<>"&List!$L$4,'Project Follow up - Base'!$AC$3:$OC$3,"<>"&List!$L$5,'Project Follow up - Base'!$AC$3:$OC$3,"<>"&List!$L$6,'Project Follow up - Base'!$AC$3:$OC$3,"<>"&List!$L$7,'Project Follow up - Base'!$AC$3:$OC$3,"<>"&List!$L$8,'Project Follow up - Base'!$AC$3:$OC$3,"<>"&List!$L$9,'Project Follow up - Base'!$AC$3:$OC$3,"<>"&List!$L$10,'Project Follow up - Base'!$AC$3:$OC$3,"<>"&List!$L$11,'Project Follow up - Base'!$AC$3:$OC$3,"<>"&List!$L$12,'Project Follow up - Base'!$AC$3:$OC$3,"<>"&List!$L$13)) -> 0 | H8: =IF('Project Follow up - Base'!$N24="",0, COUNTIFS('Project Follow up - Base'!$AC24:$OC24,"<="&10,'Project Follow up - Base'!$AC24:$OC24,">="&-10,'Project Follow up - Base'!$AC$3:$OC$3,">="&DATE(YEAR(H$3),MONTH(H$3),1),'Project Follow up - Base'!$AC$3:$OC$3,"<="&(DATE(YEAR(H$3),MONTH(H$3)+1,1)-1),'Project Follow up - Base'!$AC$4:$OC$4,"<>"&"Fri",'Project Follow up - Base'!$AC$4:$OC$4,"<>"&"Sat",'Project Follow up - Base'!$AC$3:$OC$3,"<>"&List!$L$3,'Project Follow up - Base'!$AC$3:$OC$3,"<>"&List!$L$4,'Project Follow up - Base'!$AC$3:$OC$3,"<>"&List!$L$5,'Project Follow up - Base'!$AC$3:$OC$3,"<>"&List!$L$6,'Project Follow up - Base'!$AC$3:$OC$3,"<>"&List!$L$7,'Project Follow up - Base'!$AC$3:$OC$3,"<>"&List!$L$8,'Project Follow up - Base'!$AC$3:$OC$3,"<>"&List!$L$9,'Project Follow up - Base'!$AC$3:$OC$3,"<>"&List!$L$10,'Project Follow up - Base'!$AC$3:$OC$3,"<>"&List!$L$11,'Project Follow up - Base'!$AC$3:$OC$3,"<>"&List!$L$12,'Project Follow up - Base'!$AC$3:$OC$3,"<>"&List!$L$13)) -> 0 | I8: =IF('Project Follow up - Base'!$N24="",0, COUNTIFS('Project Follow up - Base'!$AC24:$OC24,"<="&10,'Project Follow up - Base'!$AC24:$OC24,">="&-10,'Project Follow up - Base'!$AC$3:$OC$3,">="&DATE(YEAR(I$3),MONTH(I$3),1),'Project Follow up - Base'!$AC$3:$OC$3,"<="&(DATE(YEAR(I$3),MONTH(I$3)+1,1)-1),'Project Follow up - Base'!$AC$4:$OC$4,"<>"&"Fri",'Project Follow up - Base'!$AC$4:$OC$4,"<>"&"Sat",'Project Follow up - Base'!$AC$3:$OC$3,"<>"&List!$L$3,'Project Follow up - Base'!$AC$3:$OC$3,"<>"&List!$L$4,'Project Follow up - Base'!$AC$3:$OC$3,"<>"&List!$L$5,'Project Follow up - Base'!$AC$3:$OC$3,"<>"&List!$L$6,'Project Follow up - Base'!$AC$3:$OC$3,"<>"&List!$L$7,'Project Follow up - Base'!$AC$3:$OC$3,"<>"&List!$L$8,'Project Follow up - Base'!$AC$3:$OC$3,"<>"&List!$L$9,'Project Follow up - Base'!$AC$3:$OC$3,"<>"&List!$L$10,'Project Follow up - Base'!$AC$3:$OC$3,"<>"&List!$L$11,'Project Follow up - Base'!$AC$3:$OC$3,"<>"&List!$L$12,'Project Follow up - Base'!$AC$3:$OC$3,"<>"&List!$L$13)) -> 0 | J8: =IF('Project Follow up - Base'!$N24="",0, COUNTIFS('Project Follow up - Base'!$AC24:$OC24,"<="&10,'Project Follow up - Base'!$AC24:$OC24,">="&-10,'Project Follow up - Base'!$AC$3:$OC$3,">="&DATE(YEAR(J$3),MONTH(J$3),1),'Project Follow up - Base'!$AC$3:$OC$3,"<="&(DATE(YEAR(J$3),MONTH(J$3)+1,1)-1),'Project Follow up - Base'!$AC$4:$OC$4,"<>"&"Fri",'Project Follow up - Base'!$AC$4:$OC$4,"<>"&"Sat",'Project Follow up - Base'!$AC$3:$OC$3,"<>"&List!$L$3,'Project Follow up - Base'!$AC$3:$OC$3,"<>"&List!$L$4,'Project Follow up - Base'!$AC$3:$OC$3,"<>"&List!$L$5,'Project Follow up - Base'!$AC$3:$OC$3,"<>"&List!$L$6,'Project Follow up - Base'!$AC$3:$OC$3,"<>"&List!$L$7,'Project Follow up - Base'!$AC$3:$OC$3,"<>"&List!$L$8,'Project Follow up - Base'!$AC$3:$OC$3,"<>"&List!$L$9,'Project Follow up - Base'!$AC$3:$OC$3,"<>"&List!$L$10,'Project Follow up - Base'!$AC$3:$OC$3,"<>"&List!$L$11,'Project Follow up - Base'!$AC$3:$OC$3,"<>"&List!$L$12,'Project Follow up - Base'!$AC$3:$OC$3,"<>"&List!$L$13)) -> 0 | ... AL8: =IF('Project Follow up - Base'!$N24="",0, COUNTIFS('Project Follow up - Base'!$AC24:$OC24,"<="&10,'Project Follow up - Base'!$AC24:$OC24,">="&-10,'Project Follow up - Base'!$AC$3:$OC$3,">="&DATE(YEAR(AL$3),MONTH(AL$3),1),'Project Follow up - Base'!$AC$3:$OC$3,"<="&(DATE(YEAR(AL$3),MONTH(AL$3)+1,1)-1),'Project Follow up - Base'!$AC$4:$OC$4,"<>"&"Fri",'Project Follow up - Base'!$AC$4:$OC$4,"<>"&"Sat",'Project Follow up - Base'!$AC$3:$OC$3,"<>"&List!$L$3,'Project Follow up - Base'!$AC$3:$OC$3,"<>"&List!$L$4,'Project Follow up - Base'!$AC$3:$OC$3,"<>"&List!$L$5,'Project Follow up - Base'!$AC$3:$OC$3,"<>"&List!$L$6,'Project Follow up - Base'!$AC$3:$OC$3,"<>"&List!$L$7,'Project Follow up - Base'!$AC$3:$OC$3,"<>"&List!$L$8,'Project Follow up - Base'!$AC$3:$OC$3,"<>"&List!$L$9,'Project Follow up - Base'!$AC$3:$OC$3,"<>"&List!$L$10,'Project Follow up - Base'!$AC$3:$OC$3,"<>"&List!$L$11,'Project Follow up - Base'!$AC$3:$OC$3,"<>"&List!$L$12,'Project Follow up - Base'!$AC$3:$OC$3,"<>"&List!$L$13)) -> 0
A9: ='Project Follow up - Base'!$B$17 -> Studies | B9: ='Project Follow up - Base'!F25 | C9: =IF('Project Follow up - Base'!$N25="",0, COUNTIFS('Project Follow up - Base'!$AC25:$OC25,"<="&10,'Project Follow up - Base'!$AC25:$OC25,">="&-10,'Project Follow up - Base'!$AC$3:$OC$3,">="&DATE(YEAR(C$3),MONTH(C$3),1),'Project Follow up - Base'!$AC$3:$OC$3,"<="&(DATE(YEAR(C$3),MONTH(C$3)+1,1)-1),'Project Follow up - Base'!$AC$4:$OC$4,"<>"&"Fri",'Project Follow up - Base'!$AC$4:$OC$4,"<>"&"Sat",'Project Follow up - Base'!$AC$3:$OC$3,"<>"&List!$L$3,'Project Follow up - Base'!$AC$3:$OC$3,"<>"&List!$L$4,'Project Follow up - Base'!$AC$3:$OC$3,"<>"&List!$L$5,'Project Follow up - Base'!$AC$3:$OC$3,"<>"&List!$L$6,'Project Follow up - Base'!$AC$3:$OC$3,"<>"&List!$L$7,'Project Follow up - Base'!$AC$3:$OC$3,"<>"&List!$L$8,'Project Follow up - Base'!$AC$3:$OC$3,"<>"&List!$L$9,'Project Follow up - Base'!$AC$3:$OC$3,"<>"&List!$L$10,'Project Follow up - Base'!$AC$3:$OC$3,"<>"&List!$L$11,'Project Follow up - Base'!$AC$3:$OC$3,"<>"&List!$L$12,'Project Follow up - Base'!$AC$3:$OC$3,"<>"&List!$L$13)) -> 0 | D9: =IF('Project Follow up - Base'!$N25="",0, COUNTIFS('Project Follow up - Base'!$AC25:$OC25,"<="&10,'Project Follow up - Base'!$AC25:$OC25,">="&-10,'Project Follow up - Base'!$AC$3:$OC$3,">="&DATE(YEAR(D$3),MONTH(D$3),1),'Project Follow up - Base'!$AC$3:$OC$3,"<="&(DATE(YEAR(D$3),MONTH(D$3)+1,1)-1),'Project Follow up - Base'!$AC$4:$OC$4,"<>"&"Fri",'Project Follow up - Base'!$AC$4:$OC$4,"<>"&"Sat",'Project Follow up - Base'!$AC$3:$OC$3,"<>"&List!$L$3,'Project Follow up - Base'!$AC$3:$OC$3,"<>"&List!$L$4,'Project Follow up - Base'!$AC$3:$OC$3,"<>"&List!$L$5,'Project Follow up - Base'!$AC$3:$OC$3,"<>"&List!$L$6,'Project Follow up - Base'!$AC$3:$OC$3,"<>"&List!$L$7,'Project Follow up - Base'!$AC$3:$OC$3,"<>"&List!$L$8,'Project Follow up - Base'!$AC$3:$OC$3,"<>"&List!$L$9,'Project Follow up - Base'!$AC$3:$OC$3,"<>"&List!$L$10,'Project Follow up - Base'!$AC$3:$OC$3,"<>"&List!$L$11,'Project Follow up - Base'!$AC$3:$OC$3,"<>"&List!$L$12,'Project Follow up - Base'!$AC$3:$OC$3,"<>"&List!$L$13)) -> 0 | E9: =IF('Project Follow up - Base'!$N25="",0, COUNTIFS('Project Follow up - Base'!$AC25:$OC25,"<="&10,'Project Follow up - Base'!$AC25:$OC25,">="&-10,'Project Follow up - Base'!$AC$3:$OC$3,">="&DATE(YEAR(E$3),MONTH(E$3),1),'Project Follow up - Base'!$AC$3:$OC$3,"<="&(DATE(YEAR(E$3),MONTH(E$3)+1,1)-1),'Project Follow up - Base'!$AC$4:$OC$4,"<>"&"Fri",'Project Follow up - Base'!$AC$4:$OC$4,"<>"&"Sat",'Project Follow up - Base'!$AC$3:$OC$3,"<>"&List!$L$3,'Project Follow up - Base'!$AC$3:$OC$3,"<>"&List!$L$4,'Project Follow up - Base'!$AC$3:$OC$3,"<>"&List!$L$5,'Project Follow up - Base'!$AC$3:$OC$3,"<>"&List!$L$6,'Project Follow up - Base'!$AC$3:$OC$3,"<>"&List!$L$7,'Project Follow up - Base'!$AC$3:$OC$3,"<>"&List!$L$8,'Project Follow up - Base'!$AC$3:$OC$3,"<>"&List!$L$9,'Project Follow up - Base'!$AC$3:$OC$3,"<>"&List!$L$10,'Project Follow up - Base'!$AC$3:$OC$3,"<>"&List!$L$11,'Project Follow up - Base'!$AC$3:$OC$3,"<>"&List!$L$12,'Project Follow up - Base'!$AC$3:$OC$3,"<>"&List!$L$13)) -> 0 | F9: =IF('Project Follow up - Base'!$N25="",0, COUNTIFS('Project Follow up - Base'!$AC25:$OC25,"<="&10,'Project Follow up - Base'!$AC25:$OC25,">="&-10,'Project Follow up - Base'!$AC$3:$OC$3,">="&DATE(YEAR(F$3),MONTH(F$3),1),'Project Follow up - Base'!$AC$3:$OC$3,"<="&(DATE(YEAR(F$3),MONTH(F$3)+1,1)-1),'Project Follow up - Base'!$AC$4:$OC$4,"<>"&"Fri",'Project Follow up - Base'!$AC$4:$OC$4,"<>"&"Sat",'Project Follow up - Base'!$AC$3:$OC$3,"<>"&List!$L$3,'Project Follow up - Base'!$AC$3:$OC$3,"<>"&List!$L$4,'Project Follow up - Base'!$AC$3:$OC$3,"<>"&List!$L$5,'Project Follow up - Base'!$AC$3:$OC$3,"<>"&List!$L$6,'Project Follow up - Base'!$AC$3:$OC$3,"<>"&List!$L$7,'Project Follow up - Base'!$AC$3:$OC$3,"<>"&List!$L$8,'Project Follow up - Base'!$AC$3:$OC$3,"<>"&List!$L$9,'Project Follow up - Base'!$AC$3:$OC$3,"<>"&List!$L$10,'Project Follow up - Base'!$AC$3:$OC$3,"<>"&List!$L$11,'Project Follow up - Base'!$AC$3:$OC$3,"<>"&List!$L$12,'Project Follow up - Base'!$AC$3:$OC$3,"<>"&List!$L$13)) -> 0 | G9: =IF('Project Follow up - Base'!$N25="",0, COUNTIFS('Project Follow up - Base'!$AC25:$OC25,"<="&10,'Project Follow up - Base'!$AC25:$OC25,">="&-10,'Project Follow up - Base'!$AC$3:$OC$3,">="&DATE(YEAR(G$3),MONTH(G$3),1),'Project Follow up - Base'!$AC$3:$OC$3,"<="&(DATE(YEAR(G$3),MONTH(G$3)+1,1)-1),'Project Follow up - Base'!$AC$4:$OC$4,"<>"&"Fri",'Project Follow up - Base'!$AC$4:$OC$4,"<>"&"Sat",'Project Follow up - Base'!$AC$3:$OC$3,"<>"&List!$L$3,'Project Follow up - Base'!$AC$3:$OC$3,"<>"&List!$L$4,'Project Follow up - Base'!$AC$3:$OC$3,"<>"&List!$L$5,'Project Follow up - Base'!$AC$3:$OC$3,"<>"&List!$L$6,'Project Follow up - Base'!$AC$3:$OC$3,"<>"&List!$L$7,'Project Follow up - Base'!$AC$3:$OC$3,"<>"&List!$L$8,'Project Follow up - Base'!$AC$3:$OC$3,"<>"&List!$L$9,'Project Follow up - Base'!$AC$3:$OC$3,"<>"&List!$L$10,'Project Follow up - Base'!$AC$3:$OC$3,"<>"&List!$L$11,'Project Follow up - Base'!$AC$3:$OC$3,"<>"&List!$L$12,'Project Follow up - Base'!$AC$3:$OC$3,"<>"&List!$L$13)) -> 0 | H9: =IF('Project Follow up - Base'!$N25="",0, COUNTIFS('Project Follow up - Base'!$AC25:$OC25,"<="&10,'Project Follow up - Base'!$AC25:$OC25,">="&-10,'Project Follow up - Base'!$AC$3:$OC$3,">="&DATE(YEAR(H$3),MONTH(H$3),1),'Project Follow up - Base'!$AC$3:$OC$3,"<="&(DATE(YEAR(H$3),MONTH(H$3)+1,1)-1),'Project Follow up - Base'!$AC$4:$OC$4,"<>"&"Fri",'Project Follow up - Base'!$AC$4:$OC$4,"<>"&"Sat",'Project Follow up - Base'!$AC$3:$OC$3,"<>"&List!$L$3,'Project Follow up - Base'!$AC$3:$OC$3,"<>"&List!$L$4,'Project Follow up - Base'!$AC$3:$OC$3,"<>"&List!$L$5,'Project Follow up - Base'!$AC$3:$OC$3,"<>"&List!$L$6,'Project Follow up - Base'!$AC$3:$OC$3,"<>"&List!$L$7,'Project Follow up - Base'!$AC$3:$OC$3,"<>"&List!$L$8,'Project Follow up - Base'!$AC$3:$OC$3,"<>"&List!$L$9,'Project Follow up - Base'!$AC$3:$OC$3,"<>"&List!$L$10,'Project Follow up - Base'!$AC$3:$OC$3,"<>"&List!$L$11,'Project Follow up - Base'!$AC$3:$OC$3,"<>"&List!$L$12,'Project Follow up - Base'!$AC$3:$OC$3,"<>"&List!$L$13)) -> 0 | I9: =IF('Project Follow up - Base'!$N25="",0, COUNTIFS('Project Follow up - Base'!$AC25:$OC25,"<="&10,'Project Follow up - Base'!$AC25:$OC25,">="&-10,'Project Follow up - Base'!$AC$3:$OC$3,">="&DATE(YEAR(I$3),MONTH(I$3),1),'Project Follow up - Base'!$AC$3:$OC$3,"<="&(DATE(YEAR(I$3),MONTH(I$3)+1,1)-1),'Project Follow up - Base'!$AC$4:$OC$4,"<>"&"Fri",'Project Follow up - Base'!$AC$4:$OC$4,"<>"&"Sat",'Project Follow up - Base'!$AC$3:$OC$3,"<>"&List!$L$3,'Project Follow up - Base'!$AC$3:$OC$3,"<>"&List!$L$4,'Project Follow up - Base'!$AC$3:$OC$3,"<>"&List!$L$5,'Project Follow up - Base'!$AC$3:$OC$3,"<>"&List!$L$6,'Project Follow up - Base'!$AC$3:$OC$3,"<>"&List!$L$7,'Project Follow up - Base'!$AC$3:$OC$3,"<>"&List!$L$8,'Project Follow up - Base'!$AC$3:$OC$3,"<>"&List!$L$9,'Project Follow up - Base'!$AC$3:$OC$3,"<>"&List!$L$10,'Project Follow up - Base'!$AC$3:$OC$3,"<>"&List!$L$11,'Project Follow up - Base'!$AC$3:$OC$3,"<>"&List!$L$12,'Project Follow up - Base'!$AC$3:$OC$3,"<>"&List!$L$13)) -> 0 | J9: =IF('Project Follow up - Base'!$N25="",0, COUNTIFS('Project Follow up - Base'!$AC25:$OC25,"<="&10,'Project Follow up - Base'!$AC25:$OC25,">="&-10,'Project Follow up - Base'!$AC$3:$OC$3,">="&DATE(YEAR(J$3),MONTH(J$3),1),'Project Follow up - Base'!$AC$3:$OC$3,"<="&(DATE(YEAR(J$3),MONTH(J$3)+1,1)-1),'Project Follow up - Base'!$AC$4:$OC$4,"<>"&"Fri",'Project Follow up - Base'!$AC$4:$OC$4,"<>"&"Sat",'Project Follow up - Base'!$AC$3:$OC$3,"<>"&List!$L$3,'Project Follow up - Base'!$AC$3:$OC$3,"<>"&List!$L$4,'Project Follow up - Base'!$AC$3:$OC$3,"<>"&List!$L$5,'Project Follow up - Base'!$AC$3:$OC$3,"<>"&List!$L$6,'Project Follow up - Base'!$AC$3:$OC$3,"<>"&List!$L$7,'Project Follow up - Base'!$AC$3:$OC$3,"<>"&List!$L$8,'Project Follow up - Base'!$AC$3:$OC$3,"<>"&List!$L$9,'Project Follow up - Base'!$AC$3:$OC$3,"<>"&List!$L$10,'Project Follow up - Base'!$AC$3:$OC$3,"<>"&List!$L$11,'Project Follow up - Base'!$AC$3:$OC$3,"<>"&List!$L$12,'Project Follow up - Base'!$AC$3:$OC$3,"<>"&List!$L$13)) -> 0 | ... AL9: =IF('Project Follow up - Base'!$N25="",0, COUNTIFS('Project Follow up - Base'!$AC25:$OC25,"<="&10,'Project Follow up - Base'!$AC25:$OC25,">="&-10,'Project Follow up - Base'!$AC$3:$OC$3,">="&DATE(YEAR(AL$3),MONTH(AL$3),1),'Project Follow up - Base'!$AC$3:$OC$3,"<="&(DATE(YEAR(AL$3),MONTH(AL$3)+1,1)-1),'Project Follow up - Base'!$AC$4:$OC$4,"<>"&"Fri",'Project Follow up - Base'!$AC$4:$OC$4,"<>"&"Sat",'Project Follow up - Base'!$AC$3:$OC$3,"<>"&List!$L$3,'Project Follow up - Base'!$AC$3:$OC$3,"<>"&List!$L$4,'Project Follow up - Base'!$AC$3:$OC$3,"<>"&List!$L$5,'Project Follow up - Base'!$AC$3:$OC$3,"<>"&List!$L$6,'Project Follow up - Base'!$AC$3:$OC$3,"<>"&List!$L$7,'Project Follow up - Base'!$AC$3:$OC$3,"<>"&List!$L$8,'Project Follow up - Base'!$AC$3:$OC$3,"<>"&List!$L$9,'Project Follow up - Base'!$AC$3:$OC$3,"<>"&List!$L$10,'Project Follow up - Base'!$AC$3:$OC$3,"<>"&List!$L$11,'Project Follow up - Base'!$AC$3:$OC$3,"<>"&List!$L$12,'Project Follow up - Base'!$AC$3:$OC$3,"<>"&List!$L$13)) -> 0
